Workbook
Name AJEST: REGV!$C$6
Name DERx2: #REF!
Name DERx2: T_Trim!$F$3
Name FIEL: #REF!
Name INDEC: #REF!
Name REGVN: VARS!$B$6
Name REGVU: VARS!$B$7
Name VASMAY: #REF!
Name VELEC: #REF!

Sheet REGV
A1: =NA() -> #N/A | CE1: =[3]OUTM!M1 -> 0
A2: =NA() -> #N/A | B2: =[2]Pat!$B$5 -> Patentamientos Vehículos Nuevos | AC2: =[2]Pat!$D$5 -> Transferencias Vehículos Usados | BD2: Patentamientos de maquinaria en Argentina (incluye: maquinaria agrícola y vial) | CE2: =[3]OUTM!M2 -> Maq. y eqs. agrop., esp. y domest. | CF2: =[1]OUTM!$T4 -> Ciclo Clásico Mensual | CG2: Ciclo de Crecim. Mensual
A3: =NA() -> #N/A | B3: =[2]Pat!$B$3 -> Dirección Nacional de Registro de la Propiedad Automotor de Argentina (DNRPA). | AC3: =[2]Pat!$B$3 -> Dirección Nacional de Registro de la Propiedad Automotor de Argentina (DNRPA). | BD3: =[2]Pat!$B$3 -> Dirección Nacional de Registro de la Propiedad Automotor de Argentina (DNRPA).
A4: =NA() -> #N/A | B4: 1 / 3 | AC4: 2 / 3 | BD4: 3 / 3
A5: =NA() -> #N/A | B5: Pat. Vehíc. Nuevos | H5: =G10 -> REGVN-F | J5: ="Ciclo Específico: "&H10 -> Ciclo Específico: REGVN | V5: =B5 -> Pat. Vehíc. Nuevos | AC5: Transf. Vehíc. Usadados | AI5: =AH10 -> REGVU-F | AK5: ="Ciclo Específico: "&AI10 -> Ciclo Específico: REGVU | AW5: =AC5 -> Transf. Vehíc. Usadados | BD5: =BD2 -> Patentamientos de maquinaria en Argentina (incluye: maquinaria agrícola y vial) | BJ5: =BJ10 -> REMAQN | BL5: ="Ciclo Específico: "&BJ10 -> Ciclo Específico: REMAQN | BX5: =BD5 -> Patentamientos de maquinaria en Argentina (incluye: maquinaria agrícola y vial) | CE5: =[3]OUTM!$B$7 -> Índ. Base 2004=100
C6: Ajuste Estacional | J6: ="Ciclo Específico: "&H10 -> Ciclo Específico: REGVN | O6: ="Ciclo de Crecimiento: "&H10 -> Ciclo de Crecimiento: REGVN | V6: Variaciones Anuales | Y6: Prom. Anual | Z6: Bandas Críticas TCIA | AD6: =AJEST -> Ajuste Estacional | AK6: ="Ciclo Específico: "&AI10 -> Ciclo Específico: REGVU | AP6: ="Ciclo de Crecimiento: "&AI10 -> Ciclo de Crecimiento: REGVU | AW6: Variaciones Anuales | AZ6: Prom. Anual | BA6: Bandas Críticas TCIA | BE6: Ajuste Estacional | BL6: ="Ciclo Específico: "&BJ10 -> Ciclo Específico: REMAQN | BQ6: ="Ciclo de Crecimiento: "&BJ10 -> Ciclo de Crecimiento: REMAQN | BX6: Variaciones Anuales | CA6: Prom. Anual | CB6: Bandas Críticas TCIA
B7: Miles de vehículos | H7: =$B7 -> Miles de vehículos | J7: Colocar 1, -1 o No | V7: Var. Anual | W7: Var. Anuales Suavizadas | Z7: Media TCA | AA7: =+_xlfn.AGGREGATE(1,6,V11:V394) -> 0.068043152 | AC7: =$B$7 -> Miles de vehículos | AI7: =$B$7 -> Miles de vehículos | AW7: Var. Anual | AX7: Var. Anuales Suavizadas | BA7: Media TCA | BB7: =+_xlfn.AGGREGATE(1,6,AW11:AW394) -> 0.047029155 | BD7: Número de Maquinarias | BJ7: =BD7 -> Número de Maquinarias | BL7: Colocar 1, -1 o No | BX7: Var. Anual | BY7: Var. Anuales Suavizadas | CB7: Media TCA | CC7: =+_xlfn.AGGREGATE(1,6,BX11:BX394) -> 0.094779207
C8: =IF(MIN(C299:C310)<0,"NIV","LOG") -> LOG | J8: 3 | O8: λ = | Q8: =J8 -> 3 | Z8: SE TCA | AA8: =_xlfn.AGGREGATE(7,7,V23:V394) -> 0.38600963 | AD8: =IF(MIN(AD299:AD310)<0,"NIV","LOG") -> LOG | AK8: 5 | AP8: λ = | AR8: =AK8 -> 5 | BA8: SE TCA | BB8: =_xlfn.AGGREGATE(7,7,AW23:AW394) -> 0.16308872 | BE8: =IF(MIN(BE299:BE310)<0,"NIV","LOG") -> LOG | BL8: 100 | BQ8: λ = | BS8: =BL8 -> 100 | CB8: SE TCA | CC8: =_xlfn.AGGREGATE(7,7,BX23:BX394) -> 0.40715147
C9: (D16) | D9: (C17) | E9: (D12) | H9: PM 2x2 | I9: Var. Mensual | O9: 192600 | W9: =12/6.5 -> 1.8461538 | X9: =12/12.5 -> 0.96 | AA9: 0.5 | AD9: (D16) | AE9: (C17) | AF9: (D12) | AI9: PM 2x2 | AJ9: Var. Mensual | AP9: 192600 | AX9: =12/6.5 -> 1.8461538 | AY9: =12/12.5 -> 0.96 | BB9: 0.5 | BE9: (D16) | BF9: (C17) | BG9: (D12) | BJ9: PM 2x2 | BK9: Var. Mensual | BQ9: 192600 | BY9: =12/6.5 -> 1.8461538 | BZ9: =12/12.5 -> 0.96 | CC9: 0.5
A10: Meses | B10: =[2]Pat!$B10 -> REGVN | C10: =B10&"- S" -> REGVN- S | D10: =B10&"- W" -> REGVN- W | E10: =B10&"-TC" -> REGVN-TC | F10: =B10&"-A" -> REGVN-A | G10: =B10&"-F" -> REGVN-F | H10: =B10 -> REGVN | I10: ="TCM- "&H10 -> TCM- REGVN | J10: P.G. Clás. | K10: Giros ciclo clásico | L10: P.G. Cand. | M10: Máx. 19 Meses | N10: Mín. 19 Meses | O10: =H10&"-THP" -> REGVN-THP | P10: =H10&"-DTHP" -> REGVN-DTHP | Q10: P.G. Crec. | R10: Giros ciclo crecim. | S10: P.G. Cand. | T10: Máx. 19 Meses | U10: Mín. 19 Meses | V10: ="TCA-"&H10 -> TCA-REGVN | W10: ="VAS6-"&H10 -> VAS6-REGVN | X10: ="VAS12-"&H10 -> VAS12-REGVN | Y10: Prom. Anual | Z10: ="Prom. "&V10 -> Prom. TCA-REGVN | AA10: ="Banda 80% "&V10 -> Banda 80% TCA-REGVN | AC10: =[2]Pat!$D10 -> REGVU | AD10: =AC10&"- S" -> REGVU- S | AE10: =AC10&"- W" -> REGVU- W | AF10: =AC10&"-TC" -> REGVU-TC | AG10: =AC10&"-A" -> REGVU-A | AH10: =AC10&"-F" -> REGVU-F | AI10: =AC10 -> REGVU | AJ10: ="TCM- "&AI10 -> TCM- REGVU | AK10: P.G. Clás. | AL10: Giros ciclo clásico | AM10: P.G. Cand. | AN10: Máx. 19 Meses | AO10: Mín. 19 Meses | AP10: =AI10&"-THP" -> REGVU-THP | AQ10: =AI10&"-DTHP" -> REGVU-DTHP | AR10: P.G. Crec. | AS10: Giros ciclo crecim. | AT10: P.G. Cand. | AU10: Máx. 19 Meses | AV10: Mín. 19 Meses | AW10: ="TCA-"&AI10 -> TCA-REGVU | AX10: ="VAS6-"&AI10 -> VAS6-REGVU | AY10: ="VAS12-"&AI10 -> VAS12-REGVU | AZ10: Prom. Anual | BA10: ="Prom. "&AW10 -> Prom. TCA-REGVU | BB10: ="Banda 80% "&AW10 -> Banda 80% TCA-REGVU | BD10: REMAQN | BE10: =BD10&"-S" -> REMAQN-S | BF10: =BD10&"-W" -> REMAQN-W | BG10: =BD10&"-TC" -> REMAQN-TC | BH10: =BD10&"-A" -> REMAQN-A | BI10: =BD10&"-F" -> REMAQN-F | BJ10: =BD10 -> REMAQN | BK10: ="TCM-"&BJ10 -> TCM-REMAQN | BL10: P.G. Clás. | BM10: Giros ciclo clásico | BN10: P.G. Cand. | BO10: Máx. 19 Meses | BP10: Mín. 19 Meses | BQ10: =BJ10&"-THP" -> REMAQN-THP | BR10: =BJ10&"-DTHP" -> REMAQN-DTHP | BS10: P.G. Crec. | BT10: Giros ciclo crecim. | BU10: P.G. Cand. | BV10: Máx. 19 Meses | BW10: Mín. 19 Meses | BX10: ="TCA-"&BJ10 -> TCA-REMAQN | BY10: ="VAS6-"&BJ10 -> VAS6-REMAQN | BZ10: ="VAS12-"&BJ10 -> VAS12-REMAQN | CA10: Prom. Anual | CB10: ="Prom. "&BX10 -> Prom. TCA-REMAQN | CC10: ="Banda 80% "&BX10 -> Banda 80% TCA-REMAQN | CE10: =[3]OUTM!M10 -> IPIM-MEAPED | CF10: =[1]OUTM!$T10 -> Reces. Argentina | CG10: =[1]OUTM!$U10 -> Desac. Argentina
A11: 1994.01 | B11: =[2]Pat!$B11/1000 -> 64.045023 | C11: 1.69086 | D11: 1 | E11: 36.536472 | F11: =IF(C$8="NIV",B11-C11,B11/C11) -> 37.877189 | G11: =D11*F11+(1-D11)*E11 -> 37.877189 | H11: =IF(H$9="",G11,(G11^2/G12+2*G11+G12)/4) -> 37.885132 | O11: {=[4]!HP(H11:H395,$O$9)} -> 38.950395 | P11: =H11/O11-1 -> -0.027349219 | Z11: =AA$7 -> 0.068043152 | AA11: =AA$7+AA$8*AA$9 -> 0.26104797 | AB11: =AA$7-AA$8*AA$9 -> -0.12496166 | AC11: =[2]Pat!$D11/1000 -> 65.94647 | AD11: 1.0196542 | AE11: 0.41168025 | AF11: 58.943971 | AG11: =IF(AD$8="NIV",AC11-AD11,AC11/AD11) -> 64.675329 | AH11: =AG11*AE11+(1-AE11)*AF11 -> 61.303458 | AI11: =IF(AI$9="",AH11,(AH11^2/AH12+2*AH11+AH12)/4) -> 61.408933 | AP11: {=[4]!HP(AI11:AI395,$AP$9)} -> 52.880484 | AQ11: =AI11/AP11-1 -> 0.16127781 | BA11: =BB$7 -> 0.047029155 | BB11: =BB$7+BB$8*BB$9 -> 0.12857351 | BC11: =BB$7-BB$8*BB$9 -> -0.034515204 | CB11: =CC7 -> 0.094779207 | CC11: =CC7+CC9*CC8 -> 0.29835494 | CD11: =CC7-CC9*CC8 -> -0.10879653 | CE11: =[3]OUTM!M11 -> 151.64892 | CF11: =[1]OUTM!$T299 -> 0 | CG11: =[1]OUTM!$U299 -> 0
A12: 1994.02 | B12: =[2]Pat!$B12/1000 -> 34.202994 | C12: 0.92953128 | D12: 1 | E12: 37.367866 | F12: =IF(C$8="NIV",B12-C12,B12/C12) -> 36.795958 | G12: =D12*F12+(1-D12)*E12 -> 36.795958 | H12: =IF(H$9="",G12,(G11+2*G12+G13)/4) -> 37.169756 | I12: =LN(H12/H11) -> -0.019063329 | O12: 38.808112 | P12: =H12/O12-1 -> -0.042216848 | AC12: =[2]Pat!$D12/1000 -> 53.811395 | AD12: 0.95369055 | AE12: 1 | AF12: 57.898798 | AG12: =IF(AD$8="NIV",AC12-AD12,AC12/AD12) -> 56.424376 | AH12: =AG12*AE12+(1-AE12)*AF12 -> 56.424376 | AI12: =IF(AI$9="",AH12,(AH11+2*AH12+AH13)/4) -> 58.049612 | AJ12: =LN(AI12/AI11) -> -0.056257283 | AP12: 53.068541 | AQ12: =AI12/AP12-1 -> 0.0938611 | CE12: =[3]OUTM!M12 -> 148.14755 | CF12: =[1]OUTM!$T300 -> 0 | CG12: =[1]OUTM!$U300 -> 0
A13: 1994.03 | B13: =[2]Pat!$B13/1000 -> 33.899656 | C13: 1.0083423 | D13: 0.22943407 | E13: 38.279045 | F13: =IF(C$8="NIV",B13-C13,B13/C13) -> 33.619195 | G13: =D13*F13+(1-D13)*E13 -> 37.209917 | H13: =IF(H$9="",G13,(G12+2*G13+G14)/4) -> 37.787268 | I13: =LN(H13/H12) -> 0.01647681 | O13: 38.665823 | P13: =H13/O13-1 -> -0.022721751 | AC13: =[2]Pat!$D13/1000 -> 57.710664 | AD13: 0.99421884 | AE13: 1 | AF13: 56.897049 | AG13: =IF(AD$8="NIV",AC13-AD13,AC13/AD13) -> 58.046238 | AH13: =AG13*AE13+(1-AE13)*AF13 -> 58.046238 | AI13: =IF(AI$9="",AH13,(AH12+2*AH13+AH14)/4) -> 57.105521 | AJ13: =LN(AI13/AI12) -> -0.016397227 | AP13: 53.256641 | AQ13: =AI13/AP13-1 -> 0.072270417 | CE13: =[3]OUTM!M13 -> 147.71216 | CF13: =[1]OUTM!$T301 -> 0 | CG13: =[1]OUTM!$U301 -> 0
A14: 1994.04 | B14: =[2]Pat!$B14/1000 -> 40.10655 | C14: 1.004339 | D14: 1 | E14: 39.429772 | F14: =IF(C$8="NIV",B14-C14,B14/C14) -> 39.93328 | G14: =D14*F14+(1-D14)*E14 -> 39.93328 | H14: =IF(H$9="",G14,(G13+2*G14+G15)/4) -> 39.536227 | I14: =LN(H14/H13) -> 0.045245172 | O14: 38.523515 | P14: =H14/O14-1 -> 0.026288152 | AC14: =[2]Pat!$D14/1000 -> 45.845193 | AD14: 0.98078627 | AE14: 0 | AF14: 55.905231 | AG14: =IF(AD$8="NIV",AC14-AD14,AC14/AD14) -> 46.743306 | AH14: =AG14*AE14+(1-AE14)*AF14 -> 55.905231 | AI14: =IF(AI$9="",AH14,(AH13+2*AH14+AH15)/4) -> 55.891712 | AJ14: =LN(AI14/AI13) -> -0.021484704 | AP14: 53.444856 | AQ14: =AI14/AP14-1 -> 0.045782801 | CE14: =[3]OUTM!M14 -> 147.77719 | CF14: =[1]OUTM!$T302 -> 0 | CG14: =[1]OUTM!$U302 -> 0
A15: 1994.05 | B15: =[2]Pat!$B15/1000 -> 41.118574 | C15: 1.0012209 | D15: 1 | E15: 40.769852 | F15: =IF(C$8="NIV",B15-C15,B15/C15) -> 41.068432 | G15: =D15*F15+(1-D15)*E15 -> 41.068432 | H15: =IF(H$9="",G15,(G14+2*G15+G16)/4) -> 40.66908 | I15: =LN(H15/H14) -> 0.028250707 | O15: 38.381169 | P15: =H15/O15-1 -> 0.059610257 | AC15: =[2]Pat!$D15/1000 -> 52.533724 | AD15: 0.97809682 | AE15: 1 | AF15: 55.026979 | AG15: =IF(AD$8="NIV",AC15-AD15,AC15/AD15) -> 53.710147 | AH15: =AG15*AE15+(1-AE15)*AF15 -> 53.710147 | AI15: =IF(AI$9="",AH15,(AH14+2*AH15+AH16)/4) -> 55.071855 | AJ15: =LN(AI15/AI14) -> -0.014777309 | AP15: 53.633276 | AQ15: =AI15/AP15-1 -> 0.026822509 | CE15: =[3]OUTM!M15 -> 145.55216 | CF15: =[1]OUTM!$T303 -> 0 | CG15: =[1]OUTM!$U303 -> 0
A16: 1994.06 | B16: =[2]Pat!$B16/1000 -> 37.089629 | C16: 0.91339868 | D16: 1 | E16: 42.168149 | F16: =IF(C$8="NIV",B16-C16,B16/C16) -> 40.606177 | G16: =D16*F16+(1-D16)*E16 -> 40.606177 | H16: =IF(H$9="",G16,(G15+2*G16+G17)/4) -> 42.175408 | I16: =LN(H16/H15) -> 0.036369199 | O16: 38.238771 | P16: =H16/O16-1 -> 0.10294884 | AC16: =[2]Pat!$D16/1000 -> 48.030099 | AD16: 0.84319698 | AE16: 1 | AF16: 54.396275 | AG16: =IF(AD$8="NIV",AC16-AD16,AC16/AD16) -> 56.961896 | AH16: =AG16*AE16+(1-AE16)*AF16 -> 56.961896 | AI16: =IF(AI$9="",AH16,(AH15+2*AH16+AH17)/4) -> 54.920943 | AJ16: =LN(AI16/AI15) -> -0.0027440427 | AP16: 53.822003 | AQ16: =AI16/AP16-1 -> 0.020418036 | CE16: =[3]OUTM!M16 -> 142.59312 | CF16: =[1]OUTM!$T304 -> 0 | CG16: =[1]OUTM!$U304 -> 1
A17: 1994.07 | B17: =[2]Pat!$B17/1000 -> 46.790141 | C17: 1.0014363 | D17: 0.91438776 | E17: 43.193328 | F17: =IF(C$8="NIV",B17-C17,B17/C17) -> 46.723031 | G17: =D17*F17+(1-D17)*E17 -> 46.420845 | H17: =IF(H$9="",G17,(G16+2*G17+G18)/4) -> 43.832058 | I17: =LN(H17/H16) -> 0.038528177 | J17: =IF(K17="",NA(),IFERROR((H17+K17*J$8),NA())) -> 46.832058 | K17: 1 | L17: =IF(H17=M17,1,IF(H17=N17,-1,"")) -> 1 | M17: =MAX(H8:H26) -> 43.832058 | N17: =MIN(H8:H26) -> 34.524274 | O17: 38.09632 | P17: =H17/O17-1 -> 0.15055885 | Q17: =IF(R17="",NA(),IFERROR((H17+R17*Q$8),NA())) -> 46.832058 | R17: 1 | S17: =IF(P17=T17,1,IF(P17=U17,-1,"")) -> 1 | T17: =MAX(P8:P26) -> 0.15055885 | U17: =MIN(P8:P26) -> -0.062454581 | AC17: =[2]Pat!$D17/1000 -> 51.053269 | AD17: 0.98085369 | AE17: 1 | AF17: 54.209845 | AG17: =IF(AD$8="NIV",AC17-AD17,AC17/AD17) -> 52.049831 | AH17: =AG17*AE17+(1-AE17)*AF17 -> 52.049831 | AI17: =IF(AI$9="",AH17,(AH16+2*AH17+AH18)/4) -> 54.001848 | AJ17: =LN(AI17/AI16) -> -0.01687647 | AK17: =IF(AL17="",NA(),IFERROR((AI17+AL17*AK$8),NA())) -> #N/A | AM17: =IF(AI17=AN17,1,IF(AI17=AO17,-1,"")) | AN17: =MAX(AI8:AI26) -> 61.408933 | AO17: =MIN(AI8:AI26) -> 48.912898 | AP17: 54.011148 | AQ17: =AI17/AP17-1 -> -0.0001721755 | AR17: =IF(AS17="",NA(),IFERROR((AI17+AS17*AR$8),NA())) -> #N/A | AT17: =IF(AQ17=AU17,1,IF(AQ17=AV17,-1,"")) | AU17: =MAX(AQ8:AQ26) -> 0.16127781 | AV17: =MIN(AQ8:AQ26) -> -0.12266056 | CE17: =[3]OUTM!M17 -> 143.34145 | CF17: =[1]OUTM!$T305 -> 0 | CG17: =[1]OUTM!$U305 -> 1
A18: 1994.08 | B18: =[2]Pat!$B18/1000 -> 43.764074 | C18: 1.0449783 | D18: 1 | E18: 43.596542 | F18: =IF(C$8="NIV",B18-C18,B18/C18) -> 41.880366 | G18: =D18*F18+(1-D18)*E18 -> 41.880366 | H18: =IF(H$9="",G18,(G17+2*G18+G19)/4) -> 43.578144 | I18: =LN(H18/H17) -> -0.0058097401 | J18: =IF(K18="",NA(),IFERROR((H18+K18*J$8),NA())) -> #N/A | L18: =IF(H18=M18,1,IF(H18=N18,-1,"")) | M18: =MAX(H9:H27) -> 43.832058 | N18: =MIN(H9:H27) -> 32.140382 | O18: 37.953835 | P18: =H18/O18-1 -> 0.14818815 | Q18: =IF(R18="",NA(),IFERROR((H18+R18*Q$8),NA())) -> #N/A | S18: =IF(P18=T18,1,IF(P18=U18,-1,"")) | T18: =MAX(P9:P27) -> 0.15055885 | U18: =MIN(P9:P27) -> -0.12391689 | AC18: =[2]Pat!$D18/1000 -> 57.708448 | AD18: 1.0502788 | AE18: 1 | AF18: 54.468899 | AG18: =IF(AD$8="NIV",AC18-AD18,AC18/AD18) -> 54.945834 | AH18: =AG18*AE18+(1-AE18)*AF18 -> 54.945834 | AI18: =IF(AI$9="",AH18,(AH17+2*AH18+AH19)/4) -> 53.836582 | AJ18: =LN(AI18/AI17) -> -0.0030650833 | AK18: =IF(AL18="",NA(),IFERROR((AI18+AL18*AK$8),NA())) -> #N/A | AM18: =IF(AI18=AN18,1,IF(AI18=AO18,-1,"")) | AN18: =MAX(AI9:AI27) -> 61.408933 | AO18: =MIN(AI9:AI27) -> 47.44615 | AP18: 54.200826 | AQ18: =AI18/AP18-1 -> -0.0067202768 | AR18: =IF(AS18="",NA(),IFERROR((AI18+AS18*AR$8),NA())) -> #N/A | AT18: =IF(AQ18=AU18,1,IF(AQ18=AV18,-1,"")) | AU18: =MAX(AQ9:AQ27) -> 0.16127781 | AV18: =MIN(AQ9:AQ27) -> -0.15200525 | CE18: =[3]OUTM!M18 -> 149.47284 | CF18: =[1]OUTM!$T306 -> 0 | CG18: =[1]OUTM!$U306 -> 1
A19: 1994.09 | B19: =[2]Pat!$B19/1000 -> 46.987127 | C19: 1.0647193 | D19: 1 | E19: 43.404472 | F19: =IF(C$8="NIV",B19-C19,B19/C19) -> 44.130999 | G19: =D19*F19+(1-D19)*E19 -> 44.130999 | H19: =IF(H$9="",G19,(G18+2*G19+G20)/4) -> 43.276084 | I19: =LN(H19/H18) -> -0.0069555953 | J19: =IF(K19="",NA(),IFERROR((H19+K19*J$8),NA())) -> #N/A | L19: =IF(H19=M19,1,IF(H19=N19,-1,"")) | M19: =MAX(H10:H28) -> 43.832058 | N19: =MIN(H10:H28) -> 30.10787 | O19: 37.811365 | P19: =H19/O19-1 -> 0.14452582 | Q19: =IF(R19="",NA(),IFERROR((H19+R19*Q$8),NA())) -> #N/A | S19: =IF(P19=T19,1,IF(P19=U19,-1,"")) | T19: =MAX(P10:P28) -> 0.15055885 | U19: =MIN(P10:P28) -> -0.17625977 | AC19: =[2]Pat!$D19/1000 -> 54.978945 | AD19: 1.0294752 | AE19: 1 | AF19: 54.892083 | AG19: =IF(AD$8="NIV",AC19-AD19,AC19/AD19) -> 53.404826 | AH19: =AG19*AE19+(1-AE19)*AF19 -> 53.404826 | AI19: =IF(AI$9="",AH19,(AH18+2*AH19+AH20)/4) -> 54.544206 | AJ19: =LN(AI19/AI18) -> 0.013058294 | AK19: =IF(AL19="",NA(),IFERROR((AI19+AL19*AK$8),NA())) -> #N/A | AM19: =IF(AI19=AN19,1,IF(AI19=AO19,-1,"")) | AN19: =MAX(AI10:AI28) -> 61.408933 | AO19: =MIN(AI10:AI28) -> 47.121619 | AP19: 54.391154 | AQ19: =AI19/AP19-1 -> 0.0028139026 | AR19: =IF(AS19="",NA(),IFERROR((AI19+AS19*AR$8),NA())) -> #N/A | AT19: =IF(AQ19=AU19,1,IF(AQ19=AV19,-1,"")) | AU19: =MAX(AQ10:AQ28) -> 0.16127781 | AV19: =MIN(AQ10:AQ28) -> -0.16082166 | CE19: =[3]OUTM!M19 -> 151.34331 | CF19: =[1]OUTM!$T307 -> 0 | CG19: =[1]OUTM!$U307 -> 1
A20: 1994.1 | B20: =[2]Pat!$B20/1000 -> 45.744372 | C20: 0.93710385 | D20: 0.018570539 | E20: 42.851228 | F20: =IF(C$8="NIV",B20-C20,B20/C20) -> 48.814624 | G20: =D20*F20+(1-D20)*E20 -> 42.961971 | H20: =IF(H$9="",G20,(G19+2*G20+G21)/4) -> 42.608833 | I20: =LN(H20/H19) -> -0.015538572 | J20: =IF(K20="",NA(),IFERROR((H20+K20*J$8),NA())) -> #N/A | L20: =IF(H20=M20,1,IF(H20=N20,-1,"")) | M20: =MAX(H11:H29) -> 43.832058 | N20: =MIN(H11:H29) -> 28.358731 | O20: 37.668988 | P20: =H20/O20-1 -> 0.13113824 | Q20: =IF(R20="",NA(),IFERROR((H20+R20*Q$8),NA())) -> #N/A | S20: =IF(P20=T20,1,IF(P20=U20,-1,"")) | T20: =MAX(P11:P29) -> 0.15055885 | U20: =MIN(P11:P29) -> -0.22124569 | AC20: =[2]Pat!$D20/1000 -> 55.504376 | AD20: 0.983748 | AE20: 1 | AF20: 55.114516 | AG20: =IF(AD$8="NIV",AC20-AD20,AC20/AD20) -> 56.421336 | AH20: =AG20*AE20+(1-AE20)*AF20 -> 56.421336 | AI20: =IF(AI$9="",AH20,(AH19+2*AH20+AH21)/4) -> 55.144284 | AJ20: =LN(AI20/AI19) -> 0.010941614 | AK20: =IF(AL20="",NA(),IFERROR((AI20+AL20*AK$8),NA())) -> #N/A | AM20: =IF(AI20=AN20,1,IF(AI20=AO20,-1,"")) | AN20: =MAX(AI11:AI29) -> 61.408933 | AO20: =MIN(AI11:AI29) -> 47.121619 | AP20: 54.582246 | AQ20: =AI20/AP20-1 -> 0.010297089 | AR20: =IF(AS20="",NA(),IFERROR((AI20+AS20*AR$8),NA())) -> #N/A | AT20: =IF(AQ20=AU20,1,IF(AQ20=AV20,-1,"")) | AU20: =MAX(AQ11:AQ29) -> 0.16127781 | AV20: =MIN(AQ11:AQ29) -> -0.16082166 | CE20: =[3]OUTM!M20 -> 149.09969 | CF20: =[1]OUTM!$T308 -> 0 | CG20: =[1]OUTM!$U308 -> 1
A21: 1994.11 | B21: =[2]Pat!$B21/1000 -> 31.748763 | C21: 0.78624212 | D21: 1 | E21: 42.130649 | F21: =IF(C$8="NIV",B21-C21,B21/C21) -> 40.380389 | G21: =D21*F21+(1-D21)*E21 -> 40.380389 | H21: =IF(H$9="",G21,(G20+2*G21+G22)/4) -> 40.839126 | I21: =LN(H21/H20) -> -0.04242099 | J21: =IF(K21="",NA(),IFERROR((H21+K21*J$8),NA())) -> #N/A | L21: =IF(H21=M21,1,IF(H21=N21,-1,"")) | M21: =MAX(H12:H30) -> 43.832058 | N21: =MIN(H12:H30) -> 27.923923 | O21: 37.52681 | P21: =H21/O21-1 -> 0.088265319 | Q21: =IF(R21="",NA(),IFERROR((H21+R21*Q$8),NA())) -> #N/A | S21: =IF(P21=T21,1,IF(P21=U21,-1,"")) | T21: =MAX(P12:P30) -> 0.15055885 | U21: =MIN(P12:P30) -> -0.23037479 | AC21: =[2]Pat!$D21/1000 -> 58.347318 | AD21: 1.07395 | AE21: 1 | AF21: 54.855579 | AG21: =IF(AD$8="NIV",AC21-AD21,AC21/AD21) -> 54.32964 | AH21: =AG21*AE21+(1-AE21)*AF21 -> 54.32964 | AI21: =IF(AI$9="",AH21,(AH20+2*AH21+AH22)/4) -> 55.689142 | AJ21: =LN(AI21/AI20) -> 0.0098320894 | AK21: =IF(AL21="",NA(),IFERROR((AI21+AL21*AK$8),NA())) -> 60.689142 | AL21: 1 | AM21: 1 | AN21: =MAX(AI12:AI30) -> 58.049612 | AO21: =MIN(AI12:AI30) -> 47.121619 | AP21: 54.774216 | AQ21: =AI21/AP21-1 -> 0.016703581 | AR21: =IF(AS21="",NA(),IFERROR((AI21+AS21*AR$8),NA())) -> #N/A | AT21: =IF(AQ21=AU21,1,IF(AQ21=AV21,-1,"")) | AU21: =MAX(AQ12:AQ30) -> 0.0938611 | AV21: =MIN(AQ12:AQ30) -> -0.16082166 | CE21: =[3]OUTM!M21 -> 148.72074 | CF21: =[1]OUTM!$T309 -> 1 | CG21: =[1]OUTM!$U309 -> 1
A22: 1994.12 | B22: =[2]Pat!$B22/1000 -> 20.838097 | C22: 0.55529326 | D22: 0.43065209 | E22: 41.227825 | F22: =IF(C$8="NIV",B22-C22,B22/C22) -> 37.526292 | G22: =D22*F22+(1-D22)*E22 -> 39.633752 | H22: =IF(H$9="",G22,(G21+2*G22+G23)/4) -> 40.434169 | I22: =LN(H22/H21) -> -0.0099653807 | J22: =IF(K22="",NA(),IFERROR((H22+K22*J$8),NA())) -> #N/A | L22: =IF(H22=M22,1,IF(H22=N22,-1,"")) | M22: =MAX(H13:H31) -> 43.832058 | N22: =MIN(H13:H31) -> 27.923923 | O22: 37.384962 | P22: =H22/O22-1 -> 0.081562386 | Q22: =IF(R22="",NA(),IFERROR((H22+R22*Q$8),NA())) -> #N/A | S22: =IF(P22=T22,1,IF(P22=U22,-1,"")) | T22: =MAX(P13:P31) -> 0.15055885 | U22: =MIN(P13:P31) -> -0.23037479 | Y22: =AVERAGE(H11:H22) -> 40.81594 | AC22: =[2]Pat!$D22/1000 -> 61.8901 | AD22: 1.0669764 | AE22: 0.9165463 | AF22: 54.060743 | AG22: =IF(AD$8="NIV",AC22-AD22,AC22/AD22) -> 58.005126 | AH22: =AG22*AE22+(1-AE22)*AF22 -> 57.675953 | AI22: =IF(AI$9="",AH22,(AH21+2*AH22+AH23)/4) -> 55.217896 | AJ22: =LN(AI22/AI21) -> -0.0084980918 | AK22: =IF(AL22="",NA(),IFERROR((AI22+AL22*AK$8),NA())) -> #N/A | AM22: =IF(AI22=AN22,1,IF(AI22=AO22,-1,"")) | AN22: =MAX(AI13:AI31) -> 57.105521 | AO22: =MIN(AI13:AI31) -> 47.121619 | AP22: 54.967183 | AQ22: =AI22/AP22-1 -> 0.004561133 | AR22: =IF(AS22="",NA(),IFERROR((AI22+AS22*AR$8),NA())) -> #N/A | AT22: =IF(AQ22=AU22,1,IF(AQ22=AV22,-1,"")) | AU22: =MAX(AQ13:AQ31) -> 0.072270417 | AV22: =MIN(AQ13:AQ31) -> -0.16082166 | AZ22: =AVERAGE(AI11:AI22) -> 55.906878 | CE22: =[3]OUTM!M22 -> 146.41652 | CF22: =[1]OUTM!$T310 -> 1 | CG22: =[1]OUTM!$U310 -> 1
A23: 1995.01 | B23: =[2]Pat!$B23/1000 -> 73.615 | C23: 1.7490408 | D23: 1 | E23: 40.115933 | F23: =IF(C$8="NIV",B23-C23,B23/C23) -> 42.088783 | G23: =D23*F23+(1-D23)*E23 -> 42.088783 | H23: =IF(H$9="",G23,(G22+2*G23+G24)/4) -> 40.644962 | I23: =LN(H23/H22) -> 0.0051996844 | J23: =IF(K23="",NA(),IFERROR((H23+K23*J$8),NA())) -> #N/A | L23: =IF(H23=M23,1,IF(H23=N23,-1,"")) | M23: =MAX(H14:H32) -> 43.832058 | N23: =MIN(H14:H32) -> 27.713845 | O23: 37.243595 | P23: =H23/O23-1 -> 0.091327547 | Q23: =IF(R23="",NA(),IFERROR((H23+R23*Q$8),NA())) -> #N/A | S23: =IF(P23=T23,1,IF(P23=U23,-1,"")) | T23: =MAX(P14:P32) -> 0.15055885 | U23: =MIN(P14:P32) -> -0.23063746 | V23: =H23/H11-1 -> 0.0728473 | W23: =(H23/Y22)^W$9-1 -> -0.0077198622 | Y23: =Y22+(H23-H11)/12 -> 41.045926 | Z23: =Z$11 -> 0.068043152 | AA23: =AA$11 -> 0.26104797 | AB23: =AB$11 -> -0.12496166 | AC23: =[2]Pat!$D23/1000 -> 58.528 | AD23: 1.1433475 | AE23: 1 | AF23: 52.694998 | AG23: =IF(AD$8="NIV",AC23-AD23,AC23/AD23) -> 51.190037 | AH23: =AG23*AE23+(1-AE23)*AF23 -> 51.190037 | AI23: =IF(AI$9="",AH23,(AH22+2*AH23+AH24)/4) -> 52.572088 | AJ23: =LN(AI23/AI22) -> -0.04910177 | AK23: =IF(AL23="",NA(),IFERROR((AI23+AL23*AK$8),NA())) -> #N/A | AM23: =IF(AI23=AN23,1,IF(AI23=AO23,-1,"")) | AN23: =MAX(AI14:AI32) -> 55.891712 | AO23: =MIN(AI14:AI32) -> 47.121619 | AP23: 55.161269 | AQ23: =AI23/AP23-1 -> -0.046938385 | AR23: =IF(AS23="",NA(),IFERROR((AI23+AS23*AR$8),NA())) -> #N/A | AT23: =IF(AQ23=AU23,1,IF(AQ23=AV23,-1,"")) | AU23: =MAX(AQ14:AQ32) -> 0.045782801 | AV23: =MIN(AQ14:AQ32) -> -0.16082166 | AW23: =AI23/AI11-1 -> -0.14390162 | AX23: =(AI23/AZ22)^AX$9-1 -> -0.10733357 | AZ23: =AZ22+(AI23-AI11)/12 -> 55.170474 | BA23: =BA$11 -> 0.047029155 | BB23: =BB$11 -> 0.12857351 | BC23: =BC$11 -> -0.034515204 | CE23: =[3]OUTM!M23 -> 143.91589 | CF23: =[1]OUTM!$T311 -> 1 | CG23: =[1]OUTM!$U311 -> 1
A24: 1995.02 | B24: =[2]Pat!$B24/1000 -> 36.138 | C24: 0.93214783 | D24: 1 | E24: 38.658508 | F24: =IF(C$8="NIV",B24-C24,B24/C24) -> 38.768529 | G24: =D24*F24+(1-D24)*E24 -> 38.768529 | H24: =IF(H$9="",G24,(G23+2*G24+G25)/4) -> 39.334864 | I24: =LN(H24/H23) -> -0.032763625 | J24: =IF(K24="",NA(),IFERROR((H24+K24*J$8),NA())) -> #N/A | L24: =IF(H24=M24,1,IF(H24=N24,-1,"")) | M24: =MAX(H15:H33) -> 43.832058 | N24: =MIN(H15:H33) -> 27.468871 | O24: 37.102874 | P24: =H24/O24-1 -> 0.060156814 | Q24: =IF(R24="",NA(),IFERROR((H24+R24*Q$8),NA())) -> #N/A | S24: =IF(P24=T24,1,IF(P24=U24,-1,"")) | T24: =MAX(P15:P33) -> 0.15055885 | U24: =MIN(P15:P33) -> -0.23472692 | V24: =H24/H12-1 -> 0.058249203 | W24: =(H24/Y23)^W$9-1 -> -0.075599483 | Y24: =Y23+(H24-H12)/12 -> 41.226352 | Z24: =Z$11 -> 0.068043152 | AA24: =AA$11 -> 0.26104797 | AB24: =AB$11 -> -0.12496166 | AC24: =[2]Pat!$D24/1000 -> 47.662 | AD24: 0.94883128 | AE24: 1 | AF24: 50.953486 | AG24: =IF(AD$8="NIV",AC24-AD24,AC24/AD24) -> 50.232324 | AH24: =AG24*AE24+(1-AE24)*AF24 -> 50.232324 | AI24: =IF(AI$9="",AH24,(AH23+2*AH24+AH25)/4) -> 49.868394 | AJ24: =LN(AI24/AI23) -> -0.052797916 | AK24: =IF(AL24="",NA(),IFERROR((AI24+AL24*AK$8),NA())) -> #N/A | AM24: =IF(AI24=AN24,1,IF(AI24=AO24,-1,"")) | AN24: =MAX(AI15:AI33) -> 55.689142 | AO24: =MIN(AI15:AI33) -> 47.121619 | AP24: 55.356597 | AQ24: =AI24/AP24-1 -> -0.099142711 | AR24: =IF(AS24="",NA(),IFERROR((AI24+AS24*AR$8),NA())) -> #N/A | AT24: =IF(AQ24=AU24,1,IF(AQ24=AV24,-1,"")) | AU24: =MAX(AQ15:AQ33) -> 0.026822509 | AV24: =MIN(AQ15:AQ33) -> -0.16082166 | AW24: =AI24/AI12-1 -> -0.14093494 | AX24: =(AI24/AZ23)^AX$9-1 -> -0.17017158 | AZ24: =AZ23+(AI24-AI12)/12 -> 54.488706 | BA24: =BA$11 -> 0.047029155 | BB24: =BB$11 -> 0.12857351 | BC24: =BC$11 -> -0.034515204 | CE24: =[3]OUTM!M24 -> 142.98627 | CF24: =[1]OUTM!$T312 -> 1 | CG24: =[1]OUTM!$U312 -> 1
A25: 1995.03 | B25: =[2]Pat!$B25/1000 -> 41.11 | C25: 1.0900572 | D25: 1 | E25: 36.69635 | F25: =IF(C$8="NIV",B25-C25,B25/C25) -> 37.713617 | G25: =D25*F25+(1-D25)*E25 -> 37.713617 | H25: =IF(H$9="",G25,(G24+2*G25+G26)/4) -> 37.104316 | I25: =LN(H25/H24) -> -0.058377973 | J25: =IF(K25="",NA(),IFERROR((H25+K25*J$8),NA())) -> #N/A | L25: =IF(H25=M25,1,IF(H25=N25,-1,"")) | M25: =MAX(H16:H34) -> 43.832058 | N25: =MIN(H16:H34) -> 27.371593 | O25: 36.96298 | P25: =H25/O25-1 -> 0.0038237115 | Q25: =IF(R25="",NA(),IFERROR((H25+R25*Q$8),NA())) -> #N/A | S25: =IF(P25=T25,1,IF(P25=U25,-1,"")) | T25: =MAX(P16:P34) -> 0.15055885 | U25: =MIN(P16:P34) -> -0.23475392 | V25: =H25/H13-1 -> -0.018073614 | W25: =(H25/Y24)^W$9-1 -> -0.17673894 | Y25: =Y24+(H25-H13)/12 -> 41.169439 | Z25: =Z$11 -> 0.068043152 | AA25: =AA$11 -> 0.26104797 | AB25: =AB$11 -> -0.12496166 | AC25: =[2]Pat!$D25/1000 -> 50.983 | AD25: 1.0661686 | AE25: 1 | AF25: 49.390978 | AG25: =IF(AD$8="NIV",AC25-AD25,AC25/AD25) -> 47.818891 | AH25: =AG25*AE25+(1-AE25)*AF25 -> 47.818891 | AI25: =IF(AI$9="",AH25,(AH24+2*AH25+AH26)/4) -> 49.149166 | AJ25: =LN(AI25/AI24) -> -0.014527539 | AK25: =IF(AL25="",NA(),IFERROR((AI25+AL25*AK$8),NA())) -> #N/A | AM25: =IF(AI25=AN25,1,IF(AI25=AO25,-1,"")) | AN25: =MAX(AI16:AI34) -> 55.689142 | AO25: =MIN(AI16:AI34) -> 47.121619 | AP25: 55.553278 | AQ25: =AI25/AP25-1 -> -0.11527875 | AR25: =IF(AS25="",NA(),IFERROR((AI25+AS25*AR$8),NA())) -> #N/A | AT25: =IF(AQ25=AU25,1,IF(AQ25=AV25,-1,"")) | AU25: =MAX(AQ16:AQ34) -> 0.020418036 | AV25: =MIN(AQ16:AQ34) -> -0.16082166 | AW25: =AI25/AI13-1 -> -0.13932725 | AX25: =(AI25/AZ24)^AX$9-1 -> -0.17337195 | AZ25: =AZ24+(AI25-AI13)/12 -> 53.825676 | BA25: =BA$11 -> 0.047029155 | BB25: =BB$11 -> 0.12857351 | BC25: =BC$11 -> -0.034515204 | CE25: =[3]OUTM!M25 -> 138.02284 | CF25: =[1]OUTM!$T313 -> 1 | CG25: =[1]OUTM!$U313 -> 1
A26: 1995.04 | B26: =[2]Pat!$B26/1000 -> 30.375 | C26: 0.88759992 | D26: 1 | E26: 34.452082 | F26: =IF(C$8="NIV",B26-C26,B26/C26) -> 34.221499 | G26: =D26*F26+(1-D26)*E26 -> 34.221499 | H26: =IF(H$9="",G26,(G25+2*G26+G27)/4) -> 34.524274 | I26: =LN(H26/H25) -> -0.072070618 | J26: =IF(K26="",NA(),IFERROR((H26+K26*J$8),NA())) -> #N/A | L26: =IF(H26=M26,1,IF(H26=N26,-1,"")) | M26: =MAX(H17:H35) -> 43.832058 | N26: =MIN(H17:H35) -> 27.371593 | O26: 36.824108 | P26: =H26/O26-1 -> -0.062454581 | Q26: =IF(R26="",NA(),IFERROR((H26+R26*Q$8),NA())) -> #N/A | S26: =IF(P26=T26,1,IF(P26=U26,-1,"")) | T26: =MAX(P17:P35) -> 0.15055885 | U26: =MIN(P17:P35) -> -0.23475392 | V26: =H26/H14-1 -> -0.12676863 | W26: =(H26/Y25)^W$9-1 -> -0.27746181 | Y26: =Y25+(H26-H14)/12 -> 40.751776 | Z26: =Z$11 -> 0.068043152 | AA26: =AA$11 -> 0.26104797 | AB26: =AB$11 -> -0.12496166 | AC26: =[2]Pat!$D26/1000 -> 40.659 | AD26: 0.80153279 | AE26: 1 | AF26: 48.306042 | AG26: =IF(AD$8="NIV",AC26-AD26,AC26/AD26) -> 50.726558 | AH26: =AG26*AE26+(1-AE26)*AF26 -> 50.726558 | AI26: =IF(AI$9="",AH26,(AH25+2*AH26+AH27)/4) -> 48.912898 | AJ26: =LN(AI26/AI25) -> -0.0048187568 | AK26: =IF(AL26="",NA(),IFERROR((AI26+AL26*AK$8),NA())) -> #N/A | AM26: =IF(AI26=AN26,1,IF(AI26=AO26,-1,"")) | AN26: =MAX(AI17:AI35) -> 55.689142 | AO26: =MIN(AI17:AI35) -> 47.121619 | AP26: 55.751395 | AQ26: =AI26/AP26-1 -> -0.12266056 | AR26: =IF(AS26="",NA(),IFERROR((AI26+AS26*AR$8),NA())) -> #N/A | AT26: =IF(AQ26=AU26,1,IF(AQ26=AV26,-1,"")) | AU26: =MAX(AQ17:AQ35) -> 0.016703581 | AV26: =MIN(AQ17:AQ35) -> -0.16082166 | AW26: =AI26/AI14-1 -> -0.12486313 | AX26: =(AI26/AZ25)^AX$9-1 -> -0.16196419 | AZ26: =AZ25+(AI26-AI14)/12 -> 53.244108 | BA26: =BA$11 -> 0.047029155 | BB26: =BB$11 -> 0.12857351 | BC26: =BC$11 -> -0.034515204 | CE26: =[3]OUTM!M26 -> 130.61251 | CF26: =[1]OUTM!$T314 -> 1 | CG26: =[1]OUTM!$U314 -> 1
A27: 1995.05 | B27: =[2]Pat!$B27/1000 -> 28.833 | C27: 1.0362298 | D27: 0.048622708 | E27: 32.150817 | F27: =IF(C$8="NIV",B27-C27,B27/C27) -> 27.824908 | G27: =D27*F27+(1-D27)*E27 -> 31.94048 | H27: =IF(H$9="",G27,(G26+2*G27+G28)/4) -> 32.140382 | I27: =LN(H27/H26) -> -0.071549411 | J27: =IF(K27="",NA(),IFERROR((H27+K27*J$8),NA())) -> #N/A | L27: =IF(H27=M27,1,IF(H27=N27,-1,"")) | M27: =MAX(H18:H36) -> 43.578144 | N27: =MIN(H18:H36) -> 27.371593 | O27: 36.686454 | P27: =H27/O27-1 -> -0.12391689 | Q27: =IF(R27="",NA(),IFERROR((H27+R27*Q$8),NA())) -> #N/A | S27: =IF(P27=T27,1,IF(P27=U27,-1,"")) | T27: =MAX(P18:P36) -> 0.14818815 | U27: =MIN(P18:P36) -> -0.23475392 | V27: =H27/H15-1 -> -0.20970963 | W27: =(H27/Y26)^W$9-1 -> -0.35483643 | Y27: =Y26+(H27-H15)/12 -> 40.041052 | Z27: =Z$11 -> 0.068043152 | AA27: =AA$11 -> 0.26104797 | AB27: =AB$11 -> -0.12496166 | AC27: =[2]Pat!$D27/1000 -> 46.585 | AD27: 1.004429 | AE27: 1 | AF27: 47.760143 | AG27: =IF(AD$8="NIV",AC27-AD27,AC27/AD27) -> 46.379583 | AH27: =AG27*AE27+(1-AE27)*AF27 -> 46.379583 | AI27: =IF(AI$9="",AH27,(AH26+2*AH27+AH28)/4) -> 47.44615 | AJ27: =LN(AI27/AI26) -> -0.030445742 | AK27: =IF(AL27="",NA(),IFERROR((AI27+AL27*AK$8),NA())) -> #N/A | AM27: =IF(AI27=AN27,1,IF(AI27=AO27,-1,"")) | AN27: =MAX(AI18:AI36) -> 57.48435 | AO27: =MIN(AI18:AI36) -> 47.121619 | AP27: 55.950995 | AQ27: =AI27/AP27-1 -> -0.15200525 | AR27: =IF(AS27="",NA(),IFERROR((AI27+AS27*AR$8),NA())) -> #N/A | AT27: =IF(AQ27=AU27,1,IF(AQ27=AV27,-1,"")) | AU27: =MAX(AQ18:AQ36) -> 0.016703581 | AV27: =MIN(AQ18:AQ36) -> -0.16082166 | AW27: =AI27/AI15-1 -> -0.13846829 | AX27: =(AI27/AZ26)^AX$9-1 -> -0.1917197 | AZ27: =AZ26+(AI27-AI15)/12 -> 52.608633 | BA27: =BA$11 -> 0.047029155 | BB27: =BB$11 -> 0.12857351 | BC27: =BC$11 -> -0.034515204 | CE27: =[3]OUTM!M27 -> 129.13632 | CF27: =[1]OUTM!$T315 -> 1 | CG27: =[1]OUTM!$U315 -> 1
A28: 1995.06 | B28: =[2]Pat!$B28/1000 -> 27.888 | C28: 0.91558933 | D28: 1 | E28: 30.153651 | F28: =IF(C$8="NIV",B28-C28,B28/C28) -> 30.459071 | G28: =D28*F28+(1-D28)*E28 -> 30.459071 | H28: =IF(H$9="",G28,(G27+2*G28+G29)/4) -> 30.10787 | I28: =LN(H28/H27) -> -0.065326668 | J28: =IF(K28="",NA(),IFERROR((H28+K28*J$8),NA())) -> #N/A | L28: =IF(H28=M28,1,IF(H28=N28,-1,"")) | M28: =MAX(H19:H37) -> 43.276084 | N28: =MIN(H19:H37) -> 27.371593 | O28: 36.550199 | P28: =H28/O28-1 -> -0.17625977 | Q28: =IF(R28="",NA(),IFERROR((H28+R28*Q$8),NA())) -> #N/A | S28: =IF(P28=T28,1,IF(P28=U28,-1,"")) | T28: =MAX(P19:P37) -> 0.14452582 | U28: =MIN(P19:P37) -> -0.23475392 | V28: =H28/H16-1 -> -0.28612736 | W28: =(H28/Y27)^W$9-1 -> -0.4092562 | Y28: =Y27+(H28-H16)/12 -> 39.035423 | Z28: =Z$11 -> 0.068043152 | AA28: =AA$11 -> 0.26104797 | AB28: =AB$11 -> -0.12496166 | AC28: =[2]Pat!$D28/1000 -> 42.668 | AD28: 0.92157751 | AE28: 1 | AF28: 47.658937 | AG28: =IF(AD$8="NIV",AC28-AD28,AC28/AD28) -> 46.298873 | AH28: =AG28*AE28+(1-AE28)*AF28 -> 46.298873 | AI28: =IF(AI$9="",AH28,(AH27+2*AH28+AH29)/4) -> 47.121619 | AJ28: =LN(AI28/AI27) -> -0.0068634723 | AK28: =IF(AL28="",NA(),IFERROR((AI28+AL28*AK$8),NA())) -> 42.121619 | AL28: -1 | AM28: =IF(AI28=AN28,1,IF(AI28=AO28,-1,"")) -> -1 | AN28: =MAX(AI19:AI37) -> 57.48435 | AO28: =MIN(AI19:AI37) -> 47.121619 | AP28: 56.152092 | AQ28: =AI28/AP28-1 -> -0.16082166 | AR28: =IF(AS28="",NA(),IFERROR((AI28+AS28*AR$8),NA())) -> 42.121619 | AS28: -1 | AT28: =IF(AQ28=AU28,1,IF(AQ28=AV28,-1,"")) -> -1 | AU28: =MAX(AQ19:AQ37) -> 0.016703581 | AV28: =MIN(AQ19:AQ37) -> -0.16082166 | AW28: =AI28/AI16-1 -> -0.14201001 | AX28: =(AI28/AZ27)^AX$9-1 -> -0.18400803 | AZ28: =AZ27+(AI28-AI16)/12 -> 51.958689 | BA28: =BA$11 -> 0.047029155 | BB28: =BB$11 -> 0.12857351 | BC28: =BC$11 -> -0.034515204 | CE28: =[3]OUTM!M28 -> 131.54514 | CF28: =[1]OUTM!$T316 -> 1 | CG28: =[1]OUTM!$U316 -> 1
A29: 1995.07 | B29: =[2]Pat!$B29/1000 -> 27.662 | C29: 1.003233 | D29: 1 | E29: 28.768864 | F29: =IF(C$8="NIV",B29-C29,B29/C29) -> 27.572858 | G29: =D29*F29+(1-D29)*E29 -> 27.572858 | H29: =IF(H$9="",G29,(G28+2*G29+G30)/4) -> 28.358731 | I29: =LN(H29/H28) -> -0.059851633 | J29: =IF(K29="",NA(),IFERROR((H29+K29*J$8),NA())) -> #N/A | L29: =IF(H29=M29,1,IF(H29=N29,-1,"")) | M29: =MAX(H20:H38) -> 42.608833 | N29: =MIN(H20:H38) -> 27.371593 | O29: 36.415505 | P29: =H29/O29-1 -> -0.22124569 | Q29: =IF(R29="",NA(),IFERROR((H29+R29*Q$8),NA())) -> #N/A | S29: =IF(P29=T29,1,IF(P29=U29,-1,"")) | T29: =MAX(P20:P38) -> 0.13113824 | U29: =MIN(P20:P38) -> -0.23475392 | V29: =H29/H17-1 -> -0.35301393 | W29: =(H29/Y28)^W$9-1 -> -0.44562281 | X29: =(H29/Y22)^X$9-1 -> -0.2950104 | Y29: =Y28+(H29-H17)/12 -> 37.745979 | Z29: =Z$11 -> 0.068043152 | AA29: =AA$11 -> 0.26104797 | AB29: =AB$11 -> -0.12496166 | AC29: =[2]Pat!$D29/1000 -> 45.475 | AD29: 0.91851713 | AE29: 1 | AF29: 47.92979 | AG29: =IF(AD$8="NIV",AC29-AD29,AC29/AD29) -> 49.509147 | AH29: =AG29*AE29+(1-AE29)*AF29 -> 49.509147 | AI29: =IF(AI$9="",AH29,(AH28+2*AH29+AH30)/4) -> 48.748335 | AJ29: =LN(AI29/AI28) -> 0.033939139 | AK29: =IF(AL29="",NA(),IFERROR((AI29+AL29*AK$8),NA())) -> #N/A | AM29: =IF(AI29=AN29,1,IF(AI29=AO29,-1,"")) | AN29: =MAX(AI20:AI38) -> 57.48435 | AO29: =MIN(AI20:AI38) -> 47.121619 | AP29: 56.354654 | AQ29: =AI29/AP29-1 -> -0.13497233 | AR29: =IF(AS29="",NA(),IFERROR((AI29+AS29*AR$8),NA())) -> #N/A | AT29: =IF(AQ29=AU29,1,IF(AQ29=AV29,-1,"")) | AU29: =MAX(AQ20:AQ38) -> 0.016703581 | AV29: =MIN(AQ20:AQ38) -> -0.16082166 | AW29: =AI29/AI17-1 -> -0.097283957 | AX29: =(AI29/AZ28)^AX$9-1 -> -0.11107629 | AY29: =(AI29/AZ22)^AY$9-1 -> -0.12325204 | AZ29: =AZ28+(AI29-AI17)/12 -> 51.520897 | BA29: =BA$11 -> 0.047029155 | BB29: =BB$11 -> 0.12857351 | BC29: =BC$11 -> -0.034515204 | CE29: =[3]OUTM!M29 -> 129.39828 | CF29: =[1]OUTM!$T317 -> 1 | CG29: =[1]OUTM!$U317 -> 1
A30: 1995.08 | B30: =[2]Pat!$B30/1000 -> 29.343 | C30: 1.0543606 | D30: 1 | E30: 27.957224 | F30: =IF(C$8="NIV",B30-C30,B30/C30) -> 27.830138 | G30: =D30*F30+(1-D30)*E30 -> 27.830138 | H30: =IF(H$9="",G30,(G29+2*G30+G31)/4) -> 27.923923 | I30: =LN(H30/H29) -> -0.015451172 | J30: =IF(K30="",NA(),IFERROR((H30+K30*J$8),NA())) -> #N/A | L30: =IF(H30=M30,1,IF(H30=N30,-1,"")) | M30: =MAX(H21:H39) -> 40.839126 | N30: =MIN(H21:H39) -> 27.371593 | O30: 36.282496 | P30: =H30/O30-1 -> -0.23037479 | Q30: =IF(R30="",NA(),IFERROR((H30+R30*Q$8),NA())) -> #N/A | S30: =IF(P30=T30,1,IF(P30=U30,-1,"")) | T30: =MAX(P21:P39) -> 0.091327547 | U30: =MIN(P21:P39) -> -0.23475392 | V30: =H30/H18-1 -> -0.35922183 | W30: =(H30/Y29)^W$9-1 -> -0.42674342 | X30: =(H30/Y23)^X$9-1 -> -0.30912716 | Y30: =Y29+(H30-H18)/12 -> 36.441461 | Z30: =Z$11 -> 0.068043152 | AA30: =AA$11 -> 0.26104797 | AB30: =AB$11 -> -0.12496166 | AC30: =[2]Pat!$D30/1000 -> 51.374 | AD30: 1.0341779 | AE30: 1 | AF30: 48.368562 | AG30: =IF(AD$8="NIV",AC30-AD30,AC30/AD30) -> 49.676172 | AH30: =AG30*AE30+(1-AE30)*AF30 -> 49.676172 | AI30: =IF(AI$9="",AH30,(AH29+2*AH30+AH31)/4) -> 49.142359 | AJ30: =LN(AI30/AI29) -> 0.0080503264 | AK30: =IF(AL30="",NA(),IFERROR((AI30+AL30*AK$8),NA())) -> #N/A | AM30: =IF(AI30=AN30,1,IF(AI30=AO30,-1,"")) | AN30: =MAX(AI21:AI39) -> 58.310391 | AO30: =MIN(AI21:AI39) -> 47.121619 | AP30: 56.558604 | AQ30: =AI30/AP30-1 -> -0.13112498 | AR30: =IF(AS30="",NA(),IFERROR((AI30+AS30*AR$8),NA())) -> #N/A | AT30: =IF(AQ30=AU30,1,IF(AQ30=AV30,-1,"")) | AU30: =MAX(AQ21:AQ39) -> 0.016703581 | AV30: =MIN(AQ21:AQ39) -> -0.16082166 | AW30: =AI30/AI18-1 -> -0.087193925 | AX30: =(AI30/AZ29)^AX$9-1 -> -0.083561686 | AY30: =(AI30/AZ23)^AY$9-1 -> -0.10513131 | AZ30: =AZ29+(AI30-AI18)/12 -> 51.129711 | BA30: =BA$11 -> 0.047029155 | BB30: =BB$11 -> 0.12857351 | BC30: =BC$11 -> -0.034515204 | CE30: =[3]OUTM!M30 -> 124.49451 | CF30: =[1]OUTM!$T318 -> 1 | CG30: =[1]OUTM!$U318 -> 1
A31: 1995.09 | B31: =[2]Pat!$B31/1000 -> 29.21 | C31: 1.0262605 | D31: 1 | E31: 27.500163 | F31: =IF(C$8="NIV",B31-C31,B31/C31) -> 28.462559 | G31: =D31*F31+(1-D31)*E31 -> 28.462559 | H31: =IF(H$9="",G31,(G30+2*G31+G32)/4) -> 28.057696 | I31: =LN(H31/H30) -> 0.0047791638 | J31: =IF(K31="",NA(),IFERROR((H31+K31*J$8),NA())) -> #N/A | L31: =IF(H31=M31,1,IF(H31=N31,-1,"")) | M31: =MAX(H22:H40) -> 40.644962 | N31: =MIN(H22:H40) -> 27.371593 | O31: 36.151256 | P31: =H31/O31-1 -> -0.22388048 | Q31: =IF(R31="",NA(),IFERROR((H31+R31*Q$8),NA())) -> #N/A | S31: =IF(P31=T31,1,IF(P31=U31,-1,"")) | T31: =MAX(P22:P40) -> 0.091327547 | U31: =MIN(P22:P40) -> -0.23475392 | V31: =H31/H19-1 -> -0.35165816 | W31: =(H31/Y30)^W$9-1 -> -0.38286424 | X31: =(H31/Y24)^X$9-1 -> -0.3088664 | Y31: =Y30+(H31-H19)/12 -> 35.173262 | Z31: =Z$11 -> 0.068043152 | AA31: =AA$11 -> 0.26104797 | AB31: =AB$11 -> -0.12496166 | AC31: =[2]Pat!$D31/1000 -> 48.898 | AD31: 1.0249446 | AE31: 1 | AF31: 49.166014 | AG31: =IF(AD$8="NIV",AC31-AD31,AC31/AD31) -> 47.707944 | AH31: =AG31*AE31+(1-AE31)*AF31 -> 47.707944 | AI31: =IF(AI$9="",AH31,(AH30+2*AH31+AH32)/4) -> 48.501814 | AJ31: =LN(AI31/AI30) -> -0.013120172 | AK31: =IF(AL31="",NA(),IFERROR((AI31+AL31*AK$8),NA())) -> #N/A | AM31: =IF(AI31=AN31,1,IF(AI31=AO31,-1,"")) | AN31: =MAX(AI22:AI40) -> 58.310391 | AO31: =MIN(AI22:AI40) -> 47.121619 | AP31: 56.763825 | AQ31: =AI31/AP31-1 -> -0.14555065 | AR31: =IF(AS31="",NA(),IFERROR((AI31+AS31*AR$8),NA())) -> #N/A | AT31: =IF(AQ31=AU31,1,IF(AQ31=AV31,-1,"")) | AU31: =MAX(AQ22:AQ40) -> 0.004561133 | AV31: =MIN(AQ22:AQ40) -> -0.16082166 | AW31: =AI31/AI19-1 -> -0.11077972 | AX31: =(AI31/AZ30)^AX$9-1 -> -0.092817383 | AY31: =(AI31/AZ24)^AY$9-1 -> -0.10572019 | AZ31: =AZ30+(AI31-AI19)/12 -> 50.626179 | BA31: =BA$11 -> 0.047029155 | BB31: =BB$11 -> 0.12857351 | BC31: =BC$11 -> -0.034515204 | CE31: =[3]OUTM!M31 -> 123.90172 | CF31: =[1]OUTM!$T319 -> 1 | CG31: =[1]OUTM!$U319 -> 1
A32: 1995.1 | B32: =[2]Pat!$B32/1000 -> 26.796 | C32: 0.97526795 | D32: 1 | E32: 27.297286 | F32: =IF(C$8="NIV",B32-C32,B32/C32) -> 27.475526 | G32: =D32*F32+(1-D32)*E32 -> 27.475526 | H32: =IF(H$9="",G32,(G31+2*G32+G33)/4) -> 27.713845 | I32: =LN(H32/H31) -> -0.012330839 | J32: =IF(K32="",NA(),IFERROR((H32+K32*J$8),NA())) -> #N/A | L32: =IF(H32=M32,1,IF(H32=N32,-1,"")) | M32: =MAX(H23:H41) -> 40.644962 | N32: =MIN(H23:H41) -> 27.371593 | O32: 36.021828 | P32: =H32/O32-1 -> -0.23063746 | Q32: =IF(R32="",NA(),IFERROR((H32+R32*Q$8),NA())) -> #N/A | S32: =IF(P32=T32,1,IF(P32=U32,-1,"")) | T32: =MAX(P23:P41) -> 0.091327547 | U32: =MIN(P23:P41) -> -0.23475392 | V32: =H32/H20-1 -> -0.34957511 | W32: =(H32/Y31)^W$9-1 -> -0.35598825 | X32: =(H32/Y25)^X$9-1 -> -0.31609314 | Y32: =Y31+(H32-H20)/12 -> 33.932013 | Z32: =Z$11 -> 0.068043152 | AA32: =AA$11 -> 0.26104797 | AB32: =AB$11 -> -0.12496166 | AC32: =[2]Pat!$D32/1000 -> 49.392 | AD32: 1.1038275 | AE32: 0.26453581 | AF32: 50.414751 | AG32: =IF(AD$8="NIV",AC32-AD32,AC32/AD32) -> 44.746121 | AH32: =AG32*AE32+(1-AE32)*AF32 -> 48.915196 | AI32: =IF(AI$9="",AH32,(AH31+2*AH32+AH33)/4) -> 49.756502 | AJ32: =LN(AI32/AI31) -> 0.025539954 | AK32: =IF(AL32="",NA(),IFERROR((AI32+AL32*AK$8),NA())) -> #N/A | AM32: =IF(AI32=AN32,1,IF(AI32=AO32,-1,"")) | AN32: =MAX(AI23:AI41) -> 58.310391 | AO32: =MIN(AI23:AI41) -> 47.121619 | AP32: 56.970161 | AQ32: =AI32/AP32-1 -> -0.1266217 | AR32: =IF(AS32="",NA(),IFERROR((AI32+AS32*AR$8),NA())) -> #N/A | AT32: =IF(AQ32=AU32,1,IF(AQ32=AV32,-1,"")) | AU32: =MAX(AQ23:AQ41) -> -0.0019696931 | AV32: =MIN(AQ23:AQ41) -> -0.16082166 | AW32: =AI32/AI20-1 -> -0.097703366 | AX32: =(AI32/AZ31)^AX$9-1 -> -0.031483267 | AY32: =(AI32/AZ25)^AY$9-1 -> -0.072687887 | AZ32: =AZ31+(AI32-AI20)/12 -> 50.177197 | BA32: =BA$11 -> 0.047029155 | BB32: =BB$11 -> 0.12857351 | BC32: =BC$11 -> -0.034515204 | CE32: =[3]OUTM!M32 -> 125.38109 | CF32: =[1]OUTM!$T320 -> 0 | CG32: =[1]OUTM!$U320 -> 1
A33: 1995.11 | B33: =[2]Pat!$B33/1000 -> 21.743 | C33: 0.79233231 | D33: 1 | E33: 27.276989 | F33: =IF(C$8="NIV",B33-C33,B33/C33) -> 27.441769 | G33: =D33*F33+(1-D33)*E33 -> 27.441769 | H33: =IF(H$9="",G33,(G32+2*G33+G34)/4) -> 27.468871 | I33: =LN(H33/H32) -> -0.0088786938 | J33: =IF(K33="",NA(),IFERROR((H33+K33*J$8),NA())) -> #N/A | L33: =IF(H33=M33,1,IF(H33=N33,-1,"")) | M33: =MAX(H24:H42) -> 39.334864 | N33: =MIN(H24:H42) -> 27.371593 | O33: 35.894209 | P33: =H33/O33-1 -> -0.23472692 | Q33: =IF(R33="",NA(),IFERROR((H33+R33*Q$8),NA())) -> #N/A | S33: =IF(P33=T33,1,IF(P33=U33,-1,"")) | T33: =MAX(P24:P42) -> 0.060156814 | U33: =MIN(P24:P42) -> -0.23475392 | V33: =H33/H21-1 -> -0.32738835 | W33: =(H33/Y32)^W$9-1 -> -0.32301248 | X33: =(H33/Y26)^X$9-1 -> -0.3152272 | Y33: =Y32+(H33-H21)/12 -> 32.817825 | Z33: =Z$11 -> 0.068043152 | AA33: =AA$11 -> 0.26104797 | AB33: =AB$11 -> -0.12496166 | AC33: =[2]Pat!$D33/1000 -> 51.947 | AD33: 0.97119573 | AE33: 1 | AF33: 51.934881 | AG33: =IF(AD$8="NIV",AC33-AD33,AC33/AD33) -> 53.487673 | AH33: =AG33*AE33+(1-AE33)*AF33 -> 53.487673 | AI33: =IF(AI$9="",AH33,(AH32+2*AH33+AH34)/4) -> 52.240242 | AJ33: =LN(AI33/AI32) -> 0.048711966 | AK33: =IF(AL33="",NA(),IFERROR((AI33+AL33*AK$8),NA())) -> #N/A | AM33: =IF(AI33=AN33,1,IF(AI33=AO33,-1,"")) | AN33: =MAX(AI24:AI42) -> 58.310391 | AO33: =MIN(AI24:AI42) -> 47.121619 | AP33: 57.177412 | AQ33: =AI33/AP33-1 -> -0.086348256 | AR33: =IF(AS33="",NA(),IFERROR((AI33+AS33*AR$8),NA())) -> #N/A | AT33: =IF(AQ33=AU33,1,IF(AQ33=AV33,-1,"")) | AU33: =MAX(AQ24:AQ42) -> -0.0019696931 | AV33: =MIN(AQ24:AQ42) -> -0.16082166 | AW33: =AI33/AI21-1 -> -0.061931284 | AX33: =(AI33/AZ32)^AX$9-1 -> 0.077222579 | AY33: =(AI33/AZ26)^AY$9-1 -> -0.018106747 | AZ33: =AZ32+(AI33-AI21)/12 -> 49.889788 | BA33: =BA$11 -> 0.047029155 | BB33: =BB$11 -> 0.12857351 | BC33: =BC$11 -> -0.034515204 | CE33: =[3]OUTM!M33 -> 123.12322 | CF33: =[1]OUTM!$T321 -> 0 | CG33: =[1]OUTM!$U321 -> 1
A34: 1995.12 | B34: =[2]Pat!$B34/1000 -> 11.494 | C34: 0.53719642 | D34: 0 | E34: 27.516422 | F34: =IF(C$8="NIV",B34-C34,B34/C34) -> 21.396271 | G34: =D34*F34+(1-D34)*E34 -> 27.516422 | H34: =IF(H$9="",G34,(G33+2*G34+G35)/4) -> 27.371593 | I34: =LN(H34/H33) -> -0.0035476947 | J34: =IF(K34="",NA(),IFERROR((H34+K34*J$8),NA())) -> 24.371593 | K34: -1 | L34: =IF(H34=M34,1,IF(H34=N34,-1,"")) -> -1 | M34: =MAX(H25:H43) -> 37.104316 | N34: =MIN(H25:H43) -> 27.371593 | O34: 35.768354 | P34: =H34/O34-1 -> -0.23475392 | Q34: =IF(R34="",NA(),IFERROR((H34+R34*Q$8),NA())) -> 24.371593 | R34: -1 | S34: =IF(P34=T34,1,IF(P34=U34,-1,"")) -> -1 | T34: =MAX(P25:P43) -> 0.0038237115 | U34: =MIN(P25:P43) -> -0.23475392 | V34: =H34/H22-1 -> -0.32305786 | W34: =(H34/Y33)^W$9-1 -> -0.28467217 | X34: =(H34/Y27)^X$9-1 -> -0.30593073 | Y34: =Y33+(H34-H22)/12 -> 31.729277 | Z34: =Z$11 -> 0.068043152 | AA34: =AA$11 -> 0.26104797 | AB34: =AB$11 -> -0.12496166 | AC34: =[2]Pat!$D34/1000 -> 55.297 | AD34: 1.0419551 | AE34: 1 | AF34: 53.550701 | AG34: =IF(AD$8="NIV",AC34-AD34,AC34/AD34) -> 53.070426 | AH34: =AG34*AE34+(1-AE34)*AF34 -> 53.070426 | AI34: =IF(AI$9="",AH34,(AH33+2*AH34+AH35)/4) -> 53.417765 | AJ34: =LN(AI34/AI33) -> 0.022290254 | AK34: =IF(AL34="",NA(),IFERROR((AI34+AL34*AK$8),NA())) -> #N/A | AM34: =IF(AI34=AN34,1,IF(AI34=AO34,-1,"")) | AN34: =MAX(AI25:AI43) -> 58.310391 | AO34: =MIN(AI25:AI43) -> 47.121619 | AP34: 57.385342 | AQ34: =AI34/AP34-1 -> -0.069139209 | AR34: =IF(AS34="",NA(),IFERROR((AI34+AS34*AR$8),NA())) -> #N/A | AT34: =IF(AQ34=AU34,1,IF(AQ34=AV34,-1,"")) | AU34: =MAX(AQ25:AQ43) -> -0.0019696931 | AV34: =MIN(AQ25:AQ43) -> -0.16082166 | AW34: =AI34/AI22-1 -> -0.032600493 | AX34: =(AI34/AZ33)^AX$9-1 -> 0.13444348 | AY34: =(AI34/AZ27)^AY$9-1 -> 0.014760489 | AZ34: =AZ33+(AI34-AI22)/12 -> 49.739778 | BA34: =BA$11 -> 0.047029155 | BB34: =BB$11 -> 0.12857351 | BC34: =BC$11 -> -0.034515204 | CE34: =[3]OUTM!M34 -> 123.14358 | CF34: =[1]OUTM!$T322 -> 0 | CG34: =[1]OUTM!$U322 -> 1
A35: 1996.01 | B35: =[2]Pat!$B35/1000 -> 48.642 | C35: 1.8007713 | D35: 1 | E35: 28.093937 | F35: =IF(C$8="NIV",B35-C35,B35/C35) -> 27.011758 | G35: =D35*F35+(1-D35)*E35 -> 27.011758 | H35: =IF(H$9="",G35,(G34+2*G35+G36)/4) -> 27.601493 | I35: =LN(H35/H34) -> 0.0083641396 | J35: =IF(K35="",NA(),IFERROR((H35+K35*J$8),NA())) -> #N/A | L35: =IF(H35=M35,1,IF(H35=N35,-1,"")) | M35: =MAX(H26:H44) -> 34.524274 | N35: =MIN(H26:H44) -> 27.371593 | O35: 35.644177 | P35: =H35/O35-1 -> -0.22563809 | Q35: =IF(R35="",NA(),IFERROR((H35+R35*Q$8),NA())) -> #N/A | S35: =IF(P35=T35,1,IF(P35=U35,-1,"")) | T35: =MAX(P26:P44) -> -0.062454581 | U35: =MIN(P26:P44) -> -0.23475392 | V35: =H35/H23-1 -> -0.32091232 | W35: =(H35/Y34)^W$9-1 -> -0.22686252 | X35: =(H35/Y28)^X$9-1 -> -0.28304032 | Y35: =Y34+(H35-H23)/12 -> 30.642322 | Z35: =Z$11 -> 0.068043152 | AA35: =AA$11 -> 0.26104797 | AB35: =AB$11 -> -0.12496166 | AC35: =[2]Pat!$D35/1000 -> 62.671 | AD35: 1.1596606 | AE35: 1 | AF35: 55.194621 | AG35: =IF(AD$8="NIV",AC35-AD35,AC35/AD35) -> 54.042536 | AH35: =AG35*AE35+(1-AE35)*AF35 -> 54.042536 | AI35: =IF(AI$9="",AH35,(AH34+2*AH35+AH36)/4) -> 55.154512 | AJ35: =LN(AI35/AI34) -> 0.031995189 | AK35: =IF(AL35="",NA(),IFERROR((AI35+AL35*AK$8),NA())) -> #N/A | AM35: =IF(AI35=AN35,1,IF(AI35=AO35,-1,"")) | AN35: =MAX(AI26:AI44) -> 58.310391 | AO35: =MIN(AI26:AI44) -> 47.121619 | AP35: 57.59369 | AQ35: =AI35/AP35-1 -> -0.042351483 | AR35: =IF(AS35="",NA(),IFERROR((AI35+AS35*AR$8),NA())) -> #N/A | AT35: =IF(AQ35=AU35,1,IF(AQ35=AV35,-1,"")) | AU35: =MAX(AQ26:AQ44) -> -0.0019696931 | AV35: =MIN(AQ26:AQ44) -> -0.16082166 | AW35: =AI35/AI23-1 -> 0.049121587 | AX35: =(AI35/AZ34)^AX$9-1 -> 0.21018073 | AY35: =(AI35/AZ28)^AY$9-1 -> 0.058975582 | AZ35: =AZ34+(AI35-AI23)/12 -> 49.95498 | BA35: =BA$11 -> 0.047029155 | BB35: =BB$11 -> 0.12857351 | BC35: =BC$11 -> -0.034515204 | CE35: =[3]OUTM!M35 -> 127.471 | CF35: =[1]OUTM!$T323 -> 0 | CG35: =[1]OUTM!$U323 -> 0
A36: 1996.02 | B36: =[2]Pat!$B36/1000 -> 28.317 | C36: 0.98097999 | D36: 1 | E36: 28.928463 | F36: =IF(C$8="NIV",B36-C36,B36/C36) -> 28.866032 | G36: =D36*F36+(1-D36)*E36 -> 28.866032 | H36: =IF(H$9="",G36,(G35+2*G36+G37)/4) -> 28.767289 | I36: =LN(H36/H35) -> 0.041369091 | J36: =IF(K36="",NA(),IFERROR((H36+K36*J$8),NA())) -> #N/A | L36: =IF(H36=M36,1,IF(H36=N36,-1,"")) | M36: =MAX(H27:H45) -> 32.140382 | N36: =MIN(H27:H45) -> 27.371593 | O36: 35.521545 | P36: =H36/O36-1 -> -0.19014532 | Q36: =IF(R36="",NA(),IFERROR((H36+R36*Q$8),NA())) -> #N/A | S36: =IF(P36=T36,1,IF(P36=U36,-1,"")) | T36: =MAX(P27:P45) -> -0.0885906 | U36: =MIN(P27:P45) -> -0.23475392 | V36: =H36/H24-1 -> -0.26865671 | W36: =(H36/Y35)^W$9-1 -> -0.11003397 | X36: =(H36/Y29)^X$9-1 -> -0.2295453 | Y36: =Y35+(H36-H24)/12 -> 29.76169 | Z36: =Z$11 -> 0.068043152 | AA36: =AA$11 -> 0.26104797 | AB36: =AB$11 -> -0.12496166 | AC36: =[2]Pat!$D36/1000 -> 56.335 | AD36: 0.94740301 | AE36: 1 | AF36: 56.604484 | AG36: =IF(AD$8="NIV",AC36-AD36,AC36/AD36) -> 59.462551 | AH36: =AG36*AE36+(1-AE36)*AF36 -> 59.462551 | AI36: =IF(AI$9="",AH36,(AH35+2*AH36+AH37)/4) -> 57.48435 | AJ36: =LN(AI36/AI35) -> 0.041374174 | AK36: =IF(AL36="",NA(),IFERROR((AI36+AL36*AK$8),NA())) -> #N/A | AM36: =IF(AI36=AN36,1,IF(AI36=AO36,-1,"")) | AN36: =MAX(AI27:AI45) -> 58.310391 | AO36: =MIN(AI27:AI45) -> 47.121619 | AP36: 57.802174 | AQ36: =AI36/AP36-1 -> -0.0054984757 | AR36: =IF(AS36="",NA(),IFERROR((AI36+AS36*AR$8),NA())) -> #N/A | AT36: =IF(AQ36=AU36,1,IF(AQ36=AV36,-1,"")) | AU36: =MAX(AQ27:AQ45) -> -0.0019696931 | AV36: =MIN(AQ27:AQ45) -> -0.16082166 | AW36: =AI36/AI24-1 -> 0.1527211 | AX36: =(AI36/AZ35)^AX$9-1 -> 0.29587033 | AY36: =(AI36/AZ29)^AY$9-1 -> 0.11087083 | AZ36: =AZ35+(AI36-AI24)/12 -> 50.589643 | BA36: =BA$11 -> 0.047029155 | BB36: =BB$11 -> 0.12857351 | BC36: =BC$11 -> -0.034515204 | CE36: =[3]OUTM!M36 -> 128.49953 | CF36: =[1]OUTM!$T324 -> 0 | CG36: =[1]OUTM!$U324 -> 0
A37: 1996.03 | B37: =[2]Pat!$B37/1000 -> 29.717 | C37: 0.97993974 | D37: 1 | E37: 29.891438 | F37: =IF(C$8="NIV",B37-C37,B37/C37) -> 30.325334 | G37: =D37*F37+(1-D37)*E37 -> 30.325334 | H37: =IF(H$9="",G37,(G36+2*G37+G38)/4) -> 30.118118 | I37: =LN(H37/H36) -> 0.04588798 | J37: =IF(K37="",NA(),IFERROR((H37+K37*J$8),NA())) -> #N/A | L37: =IF(H37=M37,1,IF(H37=N37,-1,"")) | M37: =MAX(H28:H46) -> 31.685748 | N37: =MIN(H28:H46) -> 27.371593 | O37: 35.400284 | P37: =H37/O37-1 -> -0.14921252 | Q37: =IF(R37="",NA(),IFERROR((H37+R37*Q$8),NA())) -> #N/A | S37: =IF(P37=T37,1,IF(P37=U37,-1,"")) | T37: =MAX(P28:P46) -> -0.080486845 | U37: =MIN(P28:P46) -> -0.23475392 | V37: =H37/H25-1 -> -0.1882853 | W37: =(H37/Y36)^W$9-1 -> 0.022221631 | X37: =(H37/Y30)^X$9-1 -> -0.16719606 | Y37: =Y36+(H37-H25)/12 -> 29.179507 | Z37: =Z$11 -> 0.068043152 | AA37: =AA$11 -> 0.26104797 | AB37: =AB$11 -> -0.12496166 | AC37: =[2]Pat!$D37/1000 -> 56.369 | AD37: 0.98945475 | AE37: 1 | AF37: 57.434018 | AG37: =IF(AD$8="NIV",AC37-AD37,AC37/AD37) -> 56.969761 | AH37: =AG37*AE37+(1-AE37)*AF37 -> 56.969761 | AI37: =IF(AI$9="",AH37,(AH36+2*AH37+AH38)/4) -> 57.204697 | AJ37: =LN(AI37/AI36) -> -0.0048767142 | AK37: =IF(AL37="",NA(),IFERROR((AI37+AL37*AK$8),NA())) -> #N/A | AM37: =IF(AI37=AN37,1,IF(AI37=AO37,-1,"")) | AN37: =MAX(AI28:AI46) -> 58.310391 | AO37: =MIN(AI28:AI46) -> 47.121619 | AP37: 58.010497 | AQ37: =AI37/AP37-1 -> -0.013890577 | AR37: =IF(AS37="",NA(),IFERROR((AI37+AS37*AR$8),NA())) -> #N/A | AT37: =IF(AQ37=AU37,1,IF(AQ37=AV37,-1,"")) | AU37: =MAX(AQ28:AQ46) -> -0.0019696931 | AV37: =MIN(AQ28:AQ46) -> -0.16082166 | AW37: =AI37/AI25-1 -> 0.16389966 | AX37: =(AI37/AZ36)^AX$9-1 -> 0.25466962 | AY37: =(AI37/AZ30)^AY$9-1 -> 0.11380206 | AZ37: =AZ36+(AI37-AI25)/12 -> 51.260937 | BA37: =BA$11 -> 0.047029155 | BB37: =BB$11 -> 0.12857351 | BC37: =BC$11 -> -0.034515204 | CE37: =[3]OUTM!M37 -> 128.4299 | CF37: =[1]OUTM!$T325 -> 0 | CG37: =[1]OUTM!$U325 -> 0
A38: 1996.04 | B38: =[2]Pat!$B38/1000 -> 30.345 | C38: 0.98026948 | D38: 1 | E38: 30.687083 | F38: =IF(C$8="NIV",B38-C38,B38/C38) -> 30.955773 | G38: =D38*F38+(1-D38)*E38 -> 30.955773 | H38: =IF(H$9="",G38,(G37+2*G38+G39)/4) -> 31.110592 | I38: =LN(H38/H37) -> 0.032421392 | J38: =IF(K38="",NA(),IFERROR((H38+K38*J$8),NA())) -> #N/A | L38: =IF(H38=M38,1,IF(H38=N38,-1,"")) | M38: =MAX(H29:H47) -> 31.685748 | N38: =MIN(H29:H47) -> 27.371593 | O38: 35.280186 | P38: =H38/O38-1 -> -0.11818517 | Q38: =IF(R38="",NA(),IFERROR((H38+R38*Q$8),NA())) -> #N/A | S38: =IF(P38=T38,1,IF(P38=U38,-1,"")) | T38: =MAX(P29:P47) -> -0.077379716 | U38: =MIN(P29:P47) -> -0.23475392 | V38: =H38/H26-1 -> -0.098877747 | W38: =(H38/Y37)^W$9-1 -> 0.12558694 | X38: =(H38/Y31)^X$9-1 -> -0.11115139 | Y38: =Y37+(H38-H26)/12 -> 28.895034 | Z38: =Z$11 -> 0.068043152 | AA38: =AA$11 -> 0.26104797 | AB38: =AB$11 -> -0.12496166 | AC38: =[2]Pat!$D38/1000 -> 53.649 | AD38: 0.96810137 | AE38: 1 | AF38: 57.704022 | AG38: =IF(AD$8="NIV",AC38-AD38,AC38/AD38) -> 55.416717 | AH38: =AG38*AE38+(1-AE38)*AF38 -> 55.416717 | AI38: =IF(AI$9="",AH38,(AH37+2*AH38+AH39)/4) -> 57.068834 | AJ38: =LN(AI38/AI37) -> -0.0023778711 | AK38: =IF(AL38="",NA(),IFERROR((AI38+AL38*AK$8),NA())) -> #N/A | AM38: =IF(AI38=AN38,1,IF(AI38=AO38,-1,"")) | AN38: =MAX(AI29:AI47) -> 58.815814 | AO38: =MIN(AI29:AI47) -> 48.501814 | AP38: 58.218363 | AQ38: =AI38/AP38-1 -> -0.019745133 | AR38: =IF(AS38="",NA(),IFERROR((AI38+AS38*AR$8),NA())) -> #N/A | AT38: =IF(AQ38=AU38,1,IF(AQ38=AV38,-1,"")) | AU38: =MAX(AQ29:AQ47) -> -0.0019696931 | AV38: =MIN(AQ29:AQ47) -> -0.14555065 | AW38: =AI38/AI26-1 -> 0.16674408 | AX38: =(AI38/AZ37)^AX$9-1 -> 0.21914052 | AY38: =(AI38/AZ31)^AY$9-1 -> 0.12187093 | AZ38: =AZ37+(AI38-AI26)/12 -> 51.940598 | BA38: =BA$11 -> 0.047029155 | BB38: =BB$11 -> 0.12857351 | BC38: =BC$11 -> -0.034515204 | CE38: =[3]OUTM!M38 -> 131.70499 | CF38: =[1]OUTM!$T326 -> 0 | CG38: =[1]OUTM!$U326 -> 0
A39: 1996.05 | B39: =[2]Pat!$B39/1000 -> 34.056 | C39: 1.0197667 | D39: 0.49032075 | E39: 31.06031 | F39: =IF(C$8="NIV",B39-C39,B39/C39) -> 33.395873 | G39: =D39*F39+(1-D39)*E39 -> 32.205485 | H39: =IF(H$9="",G39,(G38+2*G39+G40)/4) -> 31.685748 | I39: =LN(H39/H38) -> 0.018318671 | J39: =IF(K39="",NA(),IFERROR((H39+K39*J$8),NA())) -> #N/A | L39: =IF(H39=M39,1,IF(H39=N39,-1,"")) | M39: =MAX(H30:H48) -> 31.929278 | N39: =MIN(H30:H48) -> 27.371593 | O39: 35.161016 | P39: =H39/O39-1 -> -0.098838653 | Q39: =IF(R39="",NA(),IFERROR((H39+R39*Q$8),NA())) -> #N/A | S39: =IF(P39=T39,1,IF(P39=U39,-1,"")) | T39: =MAX(P30:P48) -> -0.063134035 | U39: =MIN(P30:P48) -> -0.23475392 | V39: =H39/H27-1 -> -0.014145264 | W39: =(H39/Y38)^W$9-1 -> 0.18555418 | X39: =(H39/Y32)^X$9-1 -> -0.063637168 | Y39: =Y38+(H39-H27)/12 -> 28.857147 | Z39: =Z$11 -> 0.068043152 | AA39: =AA$11 -> 0.26104797 | AB39: =AB$11 -> -0.12496166 | AC39: =[2]Pat!$D39/1000 -> 61.319 | AD39: 0.97003144 | AE39: 0.50758193 | AF39: 57.646447 | AG39: =IF(AD$8="NIV",AC39-AD39,AC39/AD39) -> 63.213415 | AH39: =AG39*AE39+(1-AE39)*AF39 -> 60.472139 | AI39: =IF(AI$9="",AH39,(AH38+2*AH39+AH40)/4) -> 58.310391 | AJ39: =LN(AI39/AI38) -> 0.021522164 | AK39: =IF(AL39="",NA(),IFERROR((AI39+AL39*AK$8),NA())) -> #N/A | AM39: =IF(AI39=AN39,1,IF(AI39=AO39,-1,"")) | AN39: =MAX(AI30:AI48) -> 61.210195 | AO39: =MIN(AI30:AI48) -> 48.501814 | AP39: 58.425471 | AQ39: =AI39/AP39-1 -> -0.0019696931 | AR39: =IF(AS39="",NA(),IFERROR((AI39+AS39*AR$8),NA())) -> #N/A | AT39: =IF(AQ39=AU39,1,IF(AQ39=AV39,-1,"")) | AU39: =MAX(AQ30:AQ48) -> 0.016748082 | AV39: =MIN(AQ30:AQ48) -> -0.14555065 | AW39: =AI39/AI27-1 -> 0.22898047 | AX39: =(AI39/AZ38)^AX$9-1 -> 0.23808065 | AY39: =(AI39/AZ32)^AY$9-1 -> 0.15512764 | AZ39: =AZ38+(AI39-AI27)/12 -> 52.845952 | BA39: =BA$11 -> 0.047029155 | BB39: =BB$11 -> 0.12857351 | BC39: =BC$11 -> -0.034515204 | CE39: =[3]OUTM!M39 -> 133.28521 | CF39: =[1]OUTM!$T327 -> 0 | CG39: =[1]OUTM!$U327 -> 0
A40: 1996.06 | B40: =[2]Pat!$B40/1000 -> 26.644 | C40: 0.84917735 | D40: 1 | E40: 31.006302 | F40: =IF(C$8="NIV",B40-C40,B40/C40) -> 31.376249 | G40: =D40*F40+(1-D40)*E40 -> 31.376249 | H40: =IF(H$9="",G40,(G39+2*G40+G41)/4) -> 31.225957 | I40: =LN(H40/H39) -> -0.014617286 | J40: =IF(K40="",NA(),IFERROR((H40+K40*J$8),NA())) -> #N/A | L40: =IF(H40=M40,1,IF(H40=N40,-1,"")) | M40: =MAX(H31:H49) -> 32.523943 | N40: =MIN(H31:H49) -> 27.371593 | O40: 35.042514 | P40: =H40/O40-1 -> -0.1089122 | Q40: =IF(R40="",NA(),IFERROR((H40+R40*Q$8),NA())) -> #N/A | S40: =IF(P40=T40,1,IF(P40=U40,-1,"")) | T40: =MAX(P31:P49) -> -0.04210246 | U40: =MIN(P31:P49) -> -0.23475392 | V40: =H40/H28-1 -> 0.037136053 | W40: =(H40/Y39)^W$9-1 -> 0.15678751 | X40: =(H40/Y33)^X$9-1 -> -0.046611909 | Y40: =Y39+(H40-H28)/12 -> 28.950321 | Z40: =Z$11 -> 0.068043152 | AA40: =AA$11 -> 0.26104797 | AB40: =AB$11 -> -0.12496166 | AC40: =[2]Pat!$D40/1000 -> 46.31 | AD40: 0.81416205 | AE40: 1 | AF40: 57.282325 | AG40: =IF(AD$8="NIV",AC40-AD40,AC40/AD40) -> 56.880569 | AH40: =AG40*AE40+(1-AE40)*AF40 -> 56.880569 | AI40: =IF(AI$9="",AH40,(AH39+2*AH40+AH41)/4) -> 57.503711 | AJ40: =LN(AI40/AI39) -> -0.013930824 | AK40: =IF(AL40="",NA(),IFERROR((AI40+AL40*AK$8),NA())) -> #N/A | AM40: =IF(AI40=AN40,1,IF(AI40=AO40,-1,"")) | AN40: =MAX(AI31:AI49) -> 63.387939 | AO40: =MIN(AI31:AI49) -> 48.501814 | AP40: 58.631515 | AQ40: =AI40/AP40-1 -> -0.019235451 | AR40: =IF(AS40="",NA(),IFERROR((AI40+AS40*AR$8),NA())) -> #N/A | AT40: =IF(AQ40=AU40,1,IF(AQ40=AV40,-1,"")) | AU40: =MAX(AQ31:AQ49) -> 0.049768694 | AV40: =MIN(AQ31:AQ49) -> -0.14555065 | AW40: =AI40/AI28-1 -> 0.22032545 | AX40: =(AI40/AZ39)^AX$9-1 -> 0.16875797 | AY40: =(AI40/AZ33)^AY$9-1 -> 0.14608504 | AZ40: =AZ39+(AI40-AI28)/12 -> 53.711126 | BA40: =BA$11 -> 0.047029155 | BB40: =BB$11 -> 0.12857351 | BC40: =BC$11 -> -0.034515204 | CE40: =[3]OUTM!M40 -> 132.75486 | CF40: =[1]OUTM!$T328 -> 0 | CG40: =[1]OUTM!$U328 -> 0
...

Sheet X13
A4: ARG | B4: Desde 2002.01 | C4: Desde 1994.01 | D4: =C4 -> Desde 1994.01
A5: X13-ARIMA-SEATS
B7: ( 1 / 3 ) | C7: ( 2 / 3 ) | D7: ( 3 / 3 )
B8: ="PT-"&REGV!BD10 -> PT-REMAQN | C8: ="PT-"&REGV!B10 -> PT-REGVN | D8: ="PT-"&REGV!AC10 -> PT-REGVU
A9: Meses
A11: =REGV!A11 -> 1994.01 | C11: =REGV!B11 -> 64.045023 | D11: =REGV!AC11 -> 65.94647
A12: =REGV!A12 -> 1994.02 | C12: =REGV!B12 -> 34.202994 | D12: =REGV!AC12 -> 53.811395
A13: =REGV!A13 -> 1994.03 | C13: =REGV!B13 -> 33.899656 | D13: =REGV!AC13 -> 57.710664
A14: =REGV!A14 -> 1994.04 | C14: =REGV!B14 -> 40.10655 | D14: =REGV!AC14 -> 45.845193
A15: =REGV!A15 -> 1994.05 | C15: =REGV!B15 -> 41.118574 | D15: =REGV!AC15 -> 52.533724
A16: =REGV!A16 -> 1994.06 | C16: =REGV!B16 -> 37.089629 | D16: =REGV!AC16 -> 48.030099
A17: =REGV!A17 -> 1994.07 | C17: =REGV!B17 -> 46.790141 | D17: =REGV!AC17 -> 51.053269
A18: =REGV!A18 -> 1994.08 | C18: =REGV!B18 -> 43.764074 | D18: =REGV!AC18 -> 57.708448
A19: =REGV!A19 -> 1994.09 | C19: =REGV!B19 -> 46.987127 | D19: =REGV!AC19 -> 54.978945
A20: =REGV!A20 -> 1994.1 | C20: =REGV!B20 -> 45.744372 | D20: =REGV!AC20 -> 55.504376
A21: =REGV!A21 -> 1994.11 | C21: =REGV!B21 -> 31.748763 | D21: =REGV!AC21 -> 58.347318
A22: =REGV!A22 -> 1994.12 | C22: =REGV!B22 -> 20.838097 | D22: =REGV!AC22 -> 61.8901
... A106: =REGV!A106 -> 2001.12 | C106: =REGV!B106 -> 7.181 | D106: =REGV!AC106 -> 33.874
A107: =REGV!A107 -> 2002.01 | B107: =REGV!$BD107 -> 230.51687 | C107: =REGV!B107 -> 16.382 | D107: =REGV!AC107 -> 36.613
A108: =REGV!A108 -> 2002.02 | B108: =REGV!$BD108 -> 309.23988 | C108: =REGV!B108 -> 8.812 | D108: =REGV!AC108 -> 34.038
A109: =REGV!A109 -> 2002.03 | B109: =REGV!$BD109 -> 261.2411 | C109: =REGV!B109 -> 13.497 | D109: =REGV!AC109 -> 39.399
A110: =REGV!A110 -> 2002.04 | B110: =REGV!$BD110 -> 292.90317 | C110: =REGV!B110 -> 13.641 | D110: =REGV!AC110 -> 46.068
A111: =REGV!A111 -> 2002.05 | B111: =REGV!$BD111 -> 339.34168 | C111: =REGV!B111 -> 10.255 | D111: =REGV!AC111 -> 54.093
A112: =REGV!A112 -> 2002.06 | B112: =REGV!$BD112 -> 415.43635 | C112: =REGV!B112 -> 4.412 | D112: =REGV!AC112 -> 45.095
A113: =REGV!A113 -> 2002.07 | B113: =REGV!$BD113 -> 500.81337 | C113: =REGV!B113 -> 5.597 | D113: =REGV!AC113 -> 57.367
A114: =REGV!A114 -> 2002.08 | B114: =REGV!$BD114 -> 598.40281 | C114: =REGV!B114 -> 5.993 | D114: =REGV!AC114 -> 57.719
A115: =REGV!A115 -> 2002.09 | B115: =REGV!$BD115 -> 726.84922 | C115: =REGV!B115 -> 5.898 | D115: =REGV!AC115 -> 59.192
A116: =REGV!A116 -> 2002.1 | B116: =REGV!$BD116 -> 932.88509 | C116: =REGV!B116 -> 6.226 | D116: =REGV!AC116 -> 61.473
A117: =REGV!A117 -> 2002.11 | B117: =REGV!$BD117 -> 826.23846 | C117: =REGV!B117 -> 5.095 | D117: =REGV!AC117 -> 58.352
A118: =REGV!A118 -> 2002.12 | B118: =REGV!$BD118 -> 876.28521 | C118: =REGV!B118 -> 5.423 | D118: =REGV!AC118 -> 60.745
... A395: =REGV!A395 -> 2026.01 | B395: =REGV!$BD395 -> 889 | C395: =REGV!B395 -> 66.73 | D395: =REGV!AC395 -> 152.727
A397: =REGV!A396 -> 2026.02 | B397: =REGV!$BD396 -> #N/A | C397: =REGV!B396 -> #N/A | D397: =REGV!AC396 -> #N/A
A398: =REGV!A397 -> 2026.03 | B398: =REGV!$BD397 -> #N/A | C398: =REGV!B397 -> #N/A | D398: =REGV!AC397 -> #N/A
A399: =REGV!A398 -> 2026.04 | B399: =REGV!$BD398 -> #N/A | C399: =REGV!B398 -> #N/A | D399: =REGV!AC398 -> #N/A
A400: =REGV!A399 -> 2026.05 | B400: =REGV!$BD399 -> #N/A | C400: =REGV!B399 -> #N/A | D400: =REGV!AC399 -> #N/A
A401: =REGV!A400 -> 2026.06 | B401: =REGV!$BD400 -> #N/A | C401: =REGV!B400 -> #N/A | D401: =REGV!AC400 -> #N/A
A402: =REGV!A401 -> 2026.07 | B402: =REGV!$BD401 -> #N/A | C402: =REGV!B401 -> #N/A | D402: =REGV!AC401 -> #N/A
A403: =REGV!A402 -> 2026.08 | B403: =REGV!$BD402 -> #N/A | C403: =REGV!B402 -> #N/A | D403: =REGV!AC402 -> #N/A
A404: =REGV!A403 -> 2026.09 | B404: =REGV!$BD403 -> #N/A | C404: =REGV!B403 -> #N/A | D404: =REGV!AC403 -> #N/A
A405: =REGV!A404 -> 2026.1 | B405: =REGV!$BD404 -> #N/A | C405: =REGV!B404 -> #N/A | D405: =REGV!AC404 -> #N/A
...

Sheet FCT
I2: Serie filtrada | K2: Seguimiento de resultados en forecasts | V2: Serie filtrada | X2: Seguimiento de resultados en forecasts | AI2: Serie filtrada | AK2: Seguimiento de resultados en forecasts
I3: & forecasts | V3: & forecasts | AI3: & forecasts
B5: =REGV!$B$10 -> REGVN | K5: pegar | O5: =REGV!AC10 -> REGVU | X5: pegar | AB5: REMAQN | AK5: pegar
B6: ="Predicciones del Win X13 de: "&$B$5 -> Predicciones del Win X13 de: REGVN | K6: 1 er valor | O6: ="Predicciones del Win X13 de: "&$O$5 -> Predicciones del Win X13 de: REGVU | X6: 1 er valor | AB6: ="Predicciones del Win X13 de: "&$AB$5 -> Predicciones del Win X13 de: REMAQN | AK6: 1 er valor
B7: Sin Ajuste Estacional | E7: Ajustadas por Estacionalidad | O7: Sin Ajuste Estacional | R7: Ajustadas por Estacionalidad | AB7: Sin Ajuste Estacional | AE7: Ajustadas por Estacionalidad
B8: =REGV!C8 -> LOG | I8: ="FCT-"&$B$5 -> FCT-REGVN | K8: Estimado | L8: Real | M8: Error | O8: =REGV!AD8 -> LOG | V8: ="FCT-"&$O$5 -> FCT-REGVU | X8: Estimado | Y8: Real | Z8: Error | AB8: =REGV!BE8 -> LOG | AI8: ="FCT-"&AB5 -> FCT-REMAQN | AK8: Estimado | AL8: Real | AM8: Error
